<?xml version="1.0"?>
<robot xmlns:xacro="http://www.ros.org/wiki/xacro" >
<xacro:macro name="leko2">

<link name="base_link2">
      <inertial>
        <origin xyz="0 0 0" rpy="0 0 0"/>
        <mass value="0.5"/>
        <inertia ixx="0.1" ixy="0" ixz="0" iyy="0.1" iyz="0" izz="0.1"/>
      </inertial>
      <visual>
        <origin xyz="0 0 0" rpy="0 0 0"/>
        <geometry>
          <mesh filename="/home/samet/Desktop/isaac_robomaster/meshes/stl/mecanummain.stl" scale="0.002 0.002 0.002"/>
        </geometry>
      </visual>
      <collision>
        <origin xyz="0 0 0" rpy="0 0 0"/>
        <geometry>
          <cylinder radius="0.1" length="0.08"/>
        </geometry>
      </collision>
    </link>

    <link name="mcnN1">
      <inertial>
        <origin xyz="0 0 0" rpy="0 0 0"/>
        <mass value="0.03"/>
        <inertia ixx="0.1" ixy="0" ixz="0" iyy="0.1" iyz="0" izz="0.1"/>
      </inertial>
      <visual>
        <origin xyz="0 0 0" rpy="0 0 0"/>
        <geometry>
          <mesh filename="/home/samet/Desktop/isaac_robomaster/meshes/stl/mecanumroller.stl" scale="0.002 0.002 0.002"/>
        </geometry>
      </visual>
      <collision>
        <origin xyz="0 0 0" rpy="0 0 0"/>
        <geometry>
          <mesh filename="/home/samet/Desktop/isaac_robomaster/meshes/stl/mecanumroller.stl" scale="0.002 0.002 0.002"/>
        </geometry>
      </collision>
    </link>

    <link name="mcnN10">
      <inertial>
        <origin xyz="0 0 0" rpy="0 0 0"/>
        <mass value="0.03"/>
        <inertia ixx="0.1" ixy="0" ixz="0" iyy="0.1" iyz="0" izz="0.1"/>
      </inertial>
      <visual>
        <origin xyz="0 0 0" rpy="0 0 0"/>
        <geometry>
          <mesh filename="/home/samet/Desktop/isaac_robomaster/meshes/stl/mecanumroller.stl" scale="0.002 0.002 0.002"/>
        </geometry>
      </visual>
      <collision>
        <origin xyz="0 0 0" rpy="0 0 0"/>
        <geometry>
          <mesh filename="/home/samet/Desktop/isaac_robomaster/meshes/stl/mecanumroller.stl" scale="0.002 0.002 0.002"/>
        </geometry>
      </collision>
    </link>

    <link name="mcnN11">
      <inertial>
        <origin xyz="0 0 0" rpy="0 0 0"/>
        <mass value="0.03"/>
        <inertia ixx="0.1" ixy="0" ixz="0" iyy="0.1" iyz="0" izz="0.1"/>
      </inertial>
      <visual>
        <origin xyz="0 0 0" rpy="0 0 0"/>
        <geometry>
          <mesh filename="/home/samet/Desktop/isaac_robomaster/meshes/stl/mecanumroller.stl" scale="0.002 0.002 0.002"/>
        </geometry>
      </visual>
      <collision>
        <origin xyz="0 0 0" rpy="0 0 0"/>
        <geometry>
          <mesh filename="/home/samet/Desktop/isaac_robomaster/meshes/stl/mecanumroller.stl" scale="0.002 0.002 0.002"/>
        </geometry>
      </collision>
    </link>

    <link name="mcnN12">
      <inertial>
        <origin xyz="0 0 0" rpy="0 0 0"/>
        <mass value="0.03"/>
        <inertia ixx="0.1" ixy="0" ixz="0" iyy="0.1" iyz="0" izz="0.1"/>
      </inertial>
      <visual>
        <origin xyz="0 0 0" rpy="0 0 0"/>
        <geometry>
          <mesh filename="/home/samet/Desktop/isaac_robomaster/meshes/stl/mecanumroller.stl" scale="0.002 0.002 0.002"/>
        </geometry>
      </visual>
      <collision>
        <origin xyz="0 0 0" rpy="0 0 0"/>
        <geometry>
          <mesh filename="/home/samet/Desktop/isaac_robomaster/meshes/stl/mecanumroller.stl" scale="0.002 0.002 0.002"/>
        </geometry>
      </collision>
    </link>

    <link name="mcnN2">
      <inertial>
        <origin xyz="0 0 0" rpy="0 0 0"/>
        <mass value="0.03"/>
        <inertia ixx="0.1" ixy="0" ixz="0" iyy="0.1" iyz="0" izz="0.1"/>
      </inertial>
      <visual>
        <origin xyz="0 0 0" rpy="0 0 0"/>
        <geometry>
          <mesh filename="/home/samet/Desktop/isaac_robomaster/meshes/stl/mecanumroller.stl" scale="0.002 0.002 0.002"/>
        </geometry>
      </visual>
      <collision>
        <origin xyz="0 0 0" rpy="0 0 0"/>
        <geometry>
          <mesh filename="/home/samet/Desktop/isaac_robomaster/meshes/stl/mecanumroller.stl" scale="0.002 0.002 0.002"/>
        </geometry>
      </collision>
    </link>

    <link name="mcnN3">
      <inertial>
        <origin xyz="0 0 0" rpy="0 0 0"/>
        <mass value="0.03"/>
        <inertia ixx="0.1" ixy="0" ixz="0" iyy="0.1" iyz="0" izz="0.1"/>
      </inertial>
      <visual>
        <origin xyz="0 0 0" rpy="0 0 0"/>
        <geometry>
          <mesh filename="/home/samet/Desktop/isaac_robomaster/meshes/stl/mecanumroller.stl" scale="0.002 0.002 0.002"/>
        </geometry>
      </visual>
      <collision>
        <origin xyz="0 0 0" rpy="0 0 0"/>
        <geometry>
          <mesh filename="/home/samet/Desktop/isaac_robomaster/meshes/stl/mecanumroller.stl" scale="0.002 0.002 0.002"/>
        </geometry>
      </collision>
    </link>

    <link name="mcnN4">
      <inertial>
        <origin xyz="0 0 0" rpy="0 0 0"/>
        <mass value="0.03"/>
        <inertia ixx="0.1" ixy="0" ixz="0" iyy="0.1" iyz="0" izz="0.1"/>
      </inertial>
      <visual>
        <origin xyz="0 0 0" rpy="0 0 0"/>
        <geometry>
          <mesh filename="/home/samet/Desktop/isaac_robomaster/meshes/stl/mecanumroller.stl" scale="0.002 0.002 0.002"/>
        </geometry>
      </visual>
      <collision>
        <origin xyz="0 0 0" rpy="0 0 0"/>
        <geometry>
          <mesh filename="/home/samet/Desktop/isaac_robomaster/meshes/stl/mecanumroller.stl" scale="0.002 0.002 0.002"/>
        </geometry>
      </collision>
    </link>

    <link name="mcnN5">
      <inertial>
        <origin xyz="0 0 0" rpy="0 0 0"/>
        <mass value="0.03"/>
        <inertia ixx="0.1" ixy="0" ixz="0" iyy="0.1" iyz="0" izz="0.1"/>
      </inertial>
      <visual>
        <origin xyz="0 0 0" rpy="0 0 0"/>
        <geometry>
          <mesh filename="/home/samet/Desktop/isaac_robomaster/meshes/stl/mecanumroller.stl" scale="0.002 0.002 0.002"/>
        </geometry>
      </visual>
      <collision>
        <origin xyz="0 0 0" rpy="0 0 0"/>
        <geometry>
          <mesh filename="/home/samet/Desktop/isaac_robomaster/meshes/stl/mecanumroller.stl" scale="0.002 0.002 0.002"/>
        </geometry>
      </collision>
    </link>

    <link name="mcnN6">
      <inertial>
        <origin xyz="0 0 0" rpy="0 0 0"/>
        <mass value="0.03"/>
        <inertia ixx="0.1" ixy="0" ixz="0" iyy="0.1" iyz="0" izz="0.1"/>
      </inertial>
      <visual>
        <origin xyz="0 0 0" rpy="0 0 0"/>
        <geometry>
          <mesh filename="/home/samet/Desktop/isaac_robomaster/meshes/stl/mecanumroller.stl" scale="0.002 0.002 0.002"/>
        </geometry>
      </visual>
      <collision>
        <origin xyz="0 0 0" rpy="0 0 0"/>
        <geometry>
          <mesh filename="/home/samet/Desktop/isaac_robomaster/meshes/stl/mecanumroller.stl" scale="0.002 0.002 0.002"/>
        </geometry>
      </collision>
    </link>

    <link name="mcnN7">
      <inertial>
        <origin xyz="0 0 0" rpy="0 0 0"/>
        <mass value="0.03"/>
        <inertia ixx="0.1" ixy="0" ixz="0" iyy="0.1" iyz="0" izz="0.1"/>
      </inertial>
      <visual>
        <origin xyz="0 0 0" rpy="0 0 0"/>
        <geometry>
          <mesh filename="/home/samet/Desktop/isaac_robomaster/meshes/stl/mecanumroller.stl" scale="0.002 0.002 0.002"/>
        </geometry>
      </visual>
      <collision>
        <origin xyz="0 0 0" rpy="0 0 0"/>
        <geometry>
          <mesh filename="/home/samet/Desktop/isaac_robomaster/meshes/stl/mecanumroller.stl" scale="0.002 0.002 0.002"/>
        </geometry>
      </collision>
    </link>

    <link name="mcnN8">
      <inertial>
        <origin xyz="0 0 0" rpy="0 0 0"/>
        <mass value="0.03"/>
        <inertia ixx="0.1" ixy="0" ixz="0" iyy="0.1" iyz="0" izz="0.1"/>
      </inertial>
      <visual>
        <origin xyz="0 0 0" rpy="0 0 0"/>
        <geometry>
          <mesh filename="/home/samet/Desktop/isaac_robomaster/meshes/stl/mecanumroller.stl" scale="0.002 0.002 0.002"/>
        </geometry>
      </visual>
      <collision>
        <origin xyz="0 0 0" rpy="0 0 0"/>
        <geometry>
          <mesh filename="/home/samet/Desktop/isaac_robomaster/meshes/stl/mecanumroller.stl" scale="0.002 0.002 0.002"/>
        </geometry>
      </collision>
    </link>

    <link name="mcnN9">
      <inertial>
        <origin xyz="0 0 0" rpy="0 0 0"/>
        <mass value="0.03"/>
        <inertia ixx="0.1" ixy="0" ixz="0" iyy="0.1" iyz="0" izz="0.1"/>
      </inertial>
      <visual>
        <origin xyz="0 0 0" rpy="0 0 0"/>
        <geometry>
          <mesh filename="/home/samet/Desktop/isaac_robomaster/meshes/stl/mecanumroller.stl" scale="0.002 0.002 0.002"/>
        </geometry>
      </visual>
      <collision>
        <origin xyz="0 0 0" rpy="0 0 0"/>
        <geometry>
          <mesh filename="/home/samet/Desktop/isaac_robomaster/meshes/stl/mecanumroller.stl" scale="0.002 0.002 0.002"/>
        </geometry>
      </collision>
    </link>

    <joint name="jjoint1" type="continuous">
      <origin xyz="0.07167 -0.05076 0.02846" rpy="-1.76186 -0.79552 1.05175"/>
      <parent link="base_link2"/>
      <child link="mcnN1"/>
      <axis xyz="1.0 0 0"/>
    </joint>

    <joint name="jjoint10" type="continuous">
      <origin xyz="-0.05038 -0.07171 0.02782" rpy="0.5806 -0.79466 -0.51932"/>
      <parent link="base_link2"/>
      <child link="mcnN10"/>
      <axis xyz="1.0 0 0"/>
    </joint>

    <joint name="jjoint11" type="continuous">
      <origin xyz="-0.00767 -0.08779 0.02845" rpy="0.10036 -0.79327 0.03137"/>
      <parent link="base_link2"/>
      <child link="mcnN11"/>
      <axis xyz="1.0 0 0"/>
    </joint>

    <joint name="jjoint12" type="continuous">
      <origin xyz="0.03673 -0.07863 0.02825" rpy="0.75677 -0.79045 0.52668"/>
      <parent link="base_link2"/>
      <child link="mcnN12"/>
      <axis xyz="1.0 0 0"/>
    </joint>

    <joint name="jjoint2" type="continuous">
      <origin xyz="0.0864 -0.00753 0.02879" rpy="0.83828 -0.82486 1.56595"/>
      <parent link="base_link2"/>
      <child link="mcnN2"/>
      <axis xyz="1.0 0 0"/>
    </joint>

    <joint name="jjoint3" type="continuous">
      <origin xyz="0.08054 0.03653 0.02804" rpy="-0.91674 -0.80295 2.13129"/>
      <parent link="base_link2"/>
      <child link="mcnN3"/>
      <axis xyz="1.0 0 0"/>
    </joint>

    <joint name="jjoint4" type="continuous">
      <origin xyz="0.05184 0.06967 0.02692" rpy="-0.10837 -2.34403 -0.53781"/>
      <parent link="base_link2"/>
      <child link="mcnN4"/>
      <axis xyz="1.0 0 0"/>
    </joint>

    <joint name="jjoint5" type="continuous">
      <origin xyz="0.00816 0.08667 0.02858" rpy="0.16079 -2.35154 0.00616"/>
      <parent link="base_link2"/>
      <child link="mcnN5"/>
      <axis xyz="1.0 0 0"/>
    </joint>

    <joint name="jjoint6" type="continuous">
      <origin xyz="-0.07119 0.05132 0.02734" rpy="-0.75572 -2.34708 1.04931"/>
      <parent link="base_link2"/>
      <child link="mcnN6"/>
      <axis xyz="1.0 0 0"/>
    </joint>

    <joint name="jjoint7" type="continuous">
      <origin xyz="-0.03617 0.07901 0.0277" rpy="-1.06708 -2.36432 0.51602"/>
      <parent link="base_link2"/>
      <child link="mcnN7"/>
      <axis xyz="1.0 0 0"/>
    </joint>

    <joint name="jjoint8" type="continuous">
      <origin xyz="-0.08659 0.00832 0.02734" rpy="1.5226 -0.80215 -1.58604"/>
      <parent link="base_link2"/>
      <child link="mcnN8"/>
      <axis xyz="1.0 0 0"/>
    </joint>

    <joint name="jjoint9" type="continuous">
      <origin xyz="-0.0796 -0.03654 0.02721" rpy="0.14692 -0.78569 -1.04079"/>
      <parent link="base_link2"/>
      <child link="mcnN9"/>
      <axis xyz="1.0 0 0"/>
    </joint>

</xacro:macro>
</robot>