<?xml version="1.0"?>
<!-- created with Phobos 1.0.1 "Capricious Choutengan" -->
  <robot name="wheel">

    <link name="base_link">
      <inertial>
        <origin xyz="0 0 0" rpy="0 0 0"/>
        <mass value="0.5"/>
        <inertia ixx="0.1" ixy="0" ixz="0" iyy="0.1" iyz="0" izz="0.1"/>
      </inertial>
      <visual name="visual_0_base_link">
        <origin xyz="0 0 0" rpy="0 0 0"/>
        <geometry>
          <mesh filename="../meshes/stl/Mecanummain.stl" scale="0.002 0.002 0.002"/>
        </geometry>
      </visual>
      <collision name="collision_0_base_link">
        <origin xyz="0 0 0" rpy="0 0 0"/>
        <geometry>
          <cylinder radius="0.1" length="0.08"/>
        </geometry>
      </collision>
    </link>

    <link name="mcn1">
      <inertial>
        <origin xyz="0 0 0" rpy="0 0 0"/>
        <mass value="0.03"/>
        <inertia ixx="0.1" ixy="0" ixz="0" iyy="0.1" iyz="0" izz="0.1"/>
      </inertial>
      <visual name="visual_0_mcn1">
        <origin xyz="0 0 0" rpy="0 0 0"/>
        <geometry>
          <mesh filename="../meshes/stl/Mecanumroller.stl" scale="0.002 0.002 0.002"/>
        </geometry>
      </visual>
      <collision name="collision_0_mcn1">
        <origin xyz="0 0 0" rpy="0 0 0"/>
        <geometry>
          <mesh filename="../meshes/stl/Mecanumroller.001.stl" scale="0.002 0.002 0.002"/>
        </geometry>
      </collision>
    </link>

    <link name="mcn2">
      <inertial>
        <origin xyz="0 0 0" rpy="0 0 0"/>
        <mass value="0.03"/>
        <inertia ixx="0.1" ixy="0" ixz="0" iyy="0.1" iyz="0" izz="0.1"/>
      </inertial>
      <visual name="visual_0_mcn2">
        <origin xyz="0 0 0" rpy="0 0 0"/>
        <geometry>
          <mesh filename="../meshes/stl/Mecanumroller.002.stl" scale="0.002 0.002 0.002"/>
        </geometry>
      </visual>
      <collision name="collision_0_mcn2">
        <origin xyz="0 0 0" rpy="0 0 0"/>
        <geometry>
          <mesh filename="../meshes/stl/Mecanumroller.003.stl" scale="0.002 0.002 0.002"/>
        </geometry>
      </collision>
    </link>

    <joint name="joint1" type="continuous">
      <origin xyz="-0.0349 0.08074 0.02594" rpy="-0.31971 -2.35242 0.53919"/>
      <parent link="base_link"/>
      <child link="mcn1"/>
      <axis xyz="1.0 0 0"/>
    </joint>

    <joint name="joint2" type="continuous">
      <origin xyz="0.00727 0.08693 0.02749" rpy="-0.52461 -2.32411 0.00378"/>
      <parent link="base_link"/>
      <child link="mcn2"/>
      <axis xyz="1.0 0 0"/>
    </joint>

  </robot>