<?xml version="1.0" ?>
<!-- =================================================================================== -->
<!-- |    This document was autogenerated by xacro from test.urdf.xacro                | -->
<!-- |    EDITING THIS FILE BY HAND IS NOT RECOMMENDED                                 | -->
<!-- =================================================================================== -->
<robot name="roboke">
  <link name="base_link">
    <inertial>
      <origin rpy="0 0 0" xyz="0 0 0"/>
      <mass value="0.5"/>
      <inertia ixx="0.1" ixy="0" ixz="0" iyy="0.1" iyz="0" izz="0.1"/>
    </inertial>
    <visual name="visual_0_base_link">
      <origin rpy="0 0 0" xyz="0 0 0"/>
      <geometry>
        <mesh filename="/home/samet/Desktop/isaac_robomaster/meshes/stl/mecanummain.stl" scale="0.002 0.002 0.002"/>
      </geometry>
    </visual>
    <collision name="collision_0_base_link">
      <origin rpy="0 0 0" xyz="0 0 0"/>
      <geometry>
        <cylinder length="0.08" radius="0.1"/>
      </geometry>
    </collision>
  </link>
  <link name="mcn1">
    <inertial>
      <origin rpy="0 0 0" xyz="0 0 0"/>
      <mass value="0.03"/>
      <inertia ixx="0.1" ixy="0" ixz="0" iyy="0.1" iyz="0" izz="0.1"/>
    </inertial>
    <visual name="visual_0_mcn1">
      <origin rpy="0 0 0" xyz="0 0 0"/>
      <geometry>
        <mesh filename="/home/samet/Desktop/isaac_robomaster/meshes/stl/mecanumroller.stl" scale="0.002 0.002 0.002"/>
      </geometry>
    </visual>
    <collision name="collision_0_mcn1">
      <origin rpy="0 0 0" xyz="0 0 0"/>
      <geometry>
        <mesh filename="/home/samet/Desktop/isaac_robomaster/meshes/stl/mecanumroller.stl" scale="0.002 0.002 0.002"/>
      </geometry>
    </collision>
  </link>
  <link name="mcn10">
    <inertial>
      <origin rpy="0 0 0" xyz="0 0 0"/>
      <mass value="0.03"/>
      <inertia ixx="0.1" ixy="0" ixz="0" iyy="0.1" iyz="0" izz="0.1"/>
    </inertial>
    <visual name="visual_0_mcn10">
      <origin rpy="0 0 0" xyz="0 0 0"/>
      <geometry>
        <mesh filename="/home/samet/Desktop/isaac_robomaster/meshes/stl/mecanumroller.stl" scale="0.002 0.002 0.002"/>
      </geometry>
    </visual>
    <collision name="collision_0_mcn10">
      <origin rpy="0 0 0" xyz="0 0 0"/>
      <geometry>
        <mesh filename="/home/samet/Desktop/isaac_robomaster/meshes/stl/mecanumroller.stl" scale="0.002 0.002 0.002"/>
      </geometry>
    </collision>
  </link>
  <link name="mcn11">
    <inertial>
      <origin rpy="0 0 0" xyz="0 0 0"/>
      <mass value="0.03"/>
      <inertia ixx="0.1" ixy="0" ixz="0" iyy="0.1" iyz="0" izz="0.1"/>
    </inertial>
    <visual name="visual_0_mcn11">
      <origin rpy="0 0 0" xyz="0 0 0"/>
      <geometry>
        <mesh filename="/home/samet/Desktop/isaac_robomaster/meshes/stl/mecanumroller.stl" scale="0.002 0.002 0.002"/>
      </geometry>
    </visual>
    <collision name="collision_0_mcn11">
      <origin rpy="0 0 0" xyz="0 0 0"/>
      <geometry>
        <mesh filename="/home/samet/Desktop/isaac_robomaster/meshes/stl/mecanumroller.stl" scale="0.002 0.002 0.002"/>
      </geometry>
    </collision>
  </link>
  <link name="mcn12">
    <inertial>
      <origin rpy="0 0 0" xyz="0 0 0"/>
      <mass value="0.03"/>
      <inertia ixx="0.1" ixy="0" ixz="0" iyy="0.1" iyz="0" izz="0.1"/>
    </inertial>
    <visual name="visual_0_mcn12">
      <origin rpy="0 0 0" xyz="0 0 0"/>
      <geometry>
        <mesh filename="/home/samet/Desktop/isaac_robomaster/meshes/stl/mecanumroller.stl" scale="0.002 0.002 0.002"/>
      </geometry>
    </visual>
    <collision name="collision_0_mcn12">
      <origin rpy="0 0 0" xyz="0 0 0"/>
      <geometry>
        <mesh filename="/home/samet/Desktop/isaac_robomaster/meshes/stl/mecanumroller.stl" scale="0.002 0.002 0.002"/>
      </geometry>
    </collision>
  </link>
  <link name="mcn2">
    <inertial>
      <origin rpy="0 0 0" xyz="0 0 0"/>
      <mass value="0.03"/>
      <inertia ixx="0.1" ixy="0" ixz="0" iyy="0.1" iyz="0" izz="0.1"/>
    </inertial>
    <visual name="visual_0_mcn2">
      <origin rpy="0 0 0" xyz="0 0 0"/>
      <geometry>
        <mesh filename="/home/samet/Desktop/isaac_robomaster/meshes/stl/mecanumroller.stl" scale="0.002 0.002 0.002"/>
      </geometry>
    </visual>
    <collision name="collision_0_mcn2">
      <origin rpy="0 0 0" xyz="0 0 0"/>
      <geometry>
        <mesh filename="/home/samet/Desktop/isaac_robomaster/meshes/stl/mecanumroller.stl" scale="0.002 0.002 0.002"/>
      </geometry>
    </collision>
  </link>
  <link name="mcn3">
    <inertial>
      <origin rpy="0 0 0" xyz="0 0 0"/>
      <mass value="0.03"/>
      <inertia ixx="0.1" ixy="0" ixz="0" iyy="0.1" iyz="0" izz="0.1"/>
    </inertial>
    <visual name="visual_0_mcn3">
      <origin rpy="0 0 0" xyz="0 0 0"/>
      <geometry>
        <mesh filename="/home/samet/Desktop/isaac_robomaster/meshes/stl/mecanumroller.stl" scale="0.002 0.002 0.002"/>
      </geometry>
    </visual>
    <collision name="collision_0_mcn3">
      <origin rpy="0 0 0" xyz="0 0 0"/>
      <geometry>
        <mesh filename="/home/samet/Desktop/isaac_robomaster/meshes/stl/mecanumroller.stl" scale="0.002 0.002 0.002"/>
      </geometry>
    </collision>
  </link>
  <link name="mcn4">
    <inertial>
      <origin rpy="0 0 0" xyz="0 0 0"/>
      <mass value="0.03"/>
      <inertia ixx="0.1" ixy="0" ixz="0" iyy="0.1" iyz="0" izz="0.1"/>
    </inertial>
    <visual name="visual_0_mcn4">
      <origin rpy="0 0 0" xyz="0 0 0"/>
      <geometry>
        <mesh filename="/home/samet/Desktop/isaac_robomaster/meshes/stl/mecanumroller.stl" scale="0.002 0.002 0.002"/>
      </geometry>
    </visual>
    <collision name="collision_0_mcn4">
      <origin rpy="0 0 0" xyz="0 0 0"/>
      <geometry>
        <mesh filename="/home/samet/Desktop/isaac_robomaster/meshes/stl/mecanumroller.stl" scale="0.002 0.002 0.002"/>
      </geometry>
    </collision>
  </link>
  <link name="mcn5">
    <inertial>
      <origin rpy="0 0 0" xyz="0 0 0"/>
      <mass value="0.03"/>
      <inertia ixx="0.1" ixy="0" ixz="0" iyy="0.1" iyz="0" izz="0.1"/>
    </inertial>
    <visual name="visual_0_mcn5">
      <origin rpy="0 0 0" xyz="0 0 0"/>
      <geometry>
        <mesh filename="/home/samet/Desktop/isaac_robomaster/meshes/stl/mecanumroller.stl" scale="0.002 0.002 0.002"/>
      </geometry>
    </visual>
    <collision name="collision_0_mcn5">
      <origin rpy="0 0 0" xyz="0 0 0"/>
      <geometry>
        <mesh filename="/home/samet/Desktop/isaac_robomaster/meshes/stl/mecanumroller.stl" scale="0.002 0.002 0.002"/>
      </geometry>
    </collision>
  </link>
  <link name="mcn6">
    <inertial>
      <origin rpy="0 0 0" xyz="0 0 0"/>
      <mass value="0.03"/>
      <inertia ixx="0.1" ixy="0" ixz="0" iyy="0.1" iyz="0" izz="0.1"/>
    </inertial>
    <visual name="visual_0_mcn6">
      <origin rpy="0 0 0" xyz="0 0 0"/>
      <geometry>
        <mesh filename="/home/samet/Desktop/isaac_robomaster/meshes/stl/mecanumroller.stl" scale="0.002 0.002 0.002"/>
      </geometry>
    </visual>
    <collision name="collision_0_mcn6">
      <origin rpy="0 0 0" xyz="0 0 0"/>
      <geometry>
        <mesh filename="/home/samet/Desktop/isaac_robomaster/meshes/stl/mecanumroller.stl" scale="0.002 0.002 0.002"/>
      </geometry>
    </collision>
  </link>
  <link name="mcn7">
    <inertial>
      <origin rpy="0 0 0" xyz="0 0 0"/>
      <mass value="0.03"/>
      <inertia ixx="0.1" ixy="0" ixz="0" iyy="0.1" iyz="0" izz="0.1"/>
    </inertial>
    <visual name="visual_0_mcn7">
      <origin rpy="0 0 0" xyz="0 0 0"/>
      <geometry>
        <mesh filename="/home/samet/Desktop/isaac_robomaster/meshes/stl/mecanumroller.stl" scale="0.002 0.002 0.002"/>
      </geometry>
    </visual>
    <collision name="collision_0_mcn7">
      <origin rpy="0 0 0" xyz="0 0 0"/>
      <geometry>
        <mesh filename="/home/samet/Desktop/isaac_robomaster/meshes/stl/mecanumroller.stl" scale="0.002 0.002 0.002"/>
      </geometry>
    </collision>
  </link>
  <link name="mcn8">
    <inertial>
      <origin rpy="0 0 0" xyz="0 0 0"/>
      <mass value="0.03"/>
      <inertia ixx="0.1" ixy="0" ixz="0" iyy="0.1" iyz="0" izz="0.1"/>
    </inertial>
    <visual name="visual_0_mcn8">
      <origin rpy="0 0 0" xyz="0 0 0"/>
      <geometry>
        <mesh filename="/home/samet/Desktop/isaac_robomaster/meshes/stl/mecanumroller.stl" scale="0.002 0.002 0.002"/>
      </geometry>
    </visual>
    <collision name="collision_0_mcn8">
      <origin rpy="0 0 0" xyz="0 0 0"/>
      <geometry>
        <mesh filename="/home/samet/Desktop/isaac_robomaster/meshes/stl/mecanumroller.stl" scale="0.002 0.002 0.002"/>
      </geometry>
    </collision>
  </link>
  <link name="mcn9">
    <inertial>
      <origin rpy="0 0 0" xyz="0 0 0"/>
      <mass value="0.03"/>
      <inertia ixx="0.1" ixy="0" ixz="0" iyy="0.1" iyz="0" izz="0.1"/>
    </inertial>
    <visual name="visual_0_mcn9">
      <origin rpy="0 0 0" xyz="0 0 0"/>
      <geometry>
        <mesh filename="/home/samet/Desktop/isaac_robomaster/meshes/stl/mecanumroller.stl" scale="0.002 0.002 0.002"/>
      </geometry>
    </visual>
    <collision name="collision_0_mcn9">
      <origin rpy="0 0 0" xyz="0 0 0"/>
      <geometry>
        <mesh filename="/home/samet/Desktop/isaac_robomaster/meshes/stl/mecanumroller.stl" scale="0.002 0.002 0.002"/>
      </geometry>
    </collision>
  </link>
  <joint name="joint1" type="continuous">
    <origin rpy="-1.76186 -0.79552 1.05175" xyz="0.07167 -0.05076 0.02846"/>
    <parent link="base_link"/>
    <child link="mcn1"/>
    <axis xyz="1.0 0 0"/>
  </joint>
  <joint name="joint10" type="continuous">
    <origin rpy="0.5806 -0.79466 -0.51932" xyz="-0.05038 -0.07171 0.02782"/>
    <parent link="base_link"/>
    <child link="mcn10"/>
    <axis xyz="1.0 0 0"/>
  </joint>
  <joint name="joint11" type="continuous">
    <origin rpy="0.10036 -0.79327 0.03137" xyz="-0.00767 -0.08779 0.02845"/>
    <parent link="base_link"/>
    <child link="mcn11"/>
    <axis xyz="1.0 0 0"/>
  </joint>
  <joint name="joint12" type="continuous">
    <origin rpy="0.75677 -0.79045 0.52668" xyz="0.03673 -0.07863 0.02825"/>
    <parent link="base_link"/>
    <child link="mcn12"/>
    <axis xyz="1.0 0 0"/>
  </joint>
  <joint name="joint2" type="continuous">
    <origin rpy="0.83828 -0.82486 1.56595" xyz="0.0864 -0.00753 0.02879"/>
    <parent link="base_link"/>
    <child link="mcn2"/>
    <axis xyz="1.0 0 0"/>
  </joint>
  <joint name="joint3" type="continuous">
    <origin rpy="-0.91674 -0.80295 2.13129" xyz="0.08054 0.03653 0.02804"/>
    <parent link="base_link"/>
    <child link="mcn3"/>
    <axis xyz="1.0 0 0"/>
  </joint>
  <joint name="joint4" type="continuous">
    <origin rpy="-0.10837 -2.34403 -0.53781" xyz="0.05184 0.06967 0.02692"/>
    <parent link="base_link"/>
    <child link="mcn4"/>
    <axis xyz="1.0 0 0"/>
  </joint>
  <joint name="joint5" type="continuous">
    <origin rpy="0.16079 -2.35154 0.00616" xyz="0.00816 0.08667 0.02858"/>
    <parent link="base_link"/>
    <child link="mcn5"/>
    <axis xyz="1.0 0 0"/>
  </joint>
  <joint name="joint6" type="continuous">
    <origin rpy="-0.75572 -2.34708 1.04931" xyz="-0.07119 0.05132 0.02734"/>
    <parent link="base_link"/>
    <child link="mcn6"/>
    <axis xyz="1.0 0 0"/>
  </joint>
  <joint name="joint7" type="continuous">
    <origin rpy="-1.06708 -2.36432 0.51602" xyz="-0.03617 0.07901 0.0277"/>
    <parent link="base_link"/>
    <child link="mcn7"/>
    <axis xyz="1.0 0 0"/>
  </joint>
  <joint name="joint8" type="continuous">
    <origin rpy="1.5226 -0.80215 -1.58604" xyz="-0.08659 0.00832 0.02734"/>
    <parent link="base_link"/>
    <child link="mcn8"/>
    <axis xyz="1.0 0 0"/>
  </joint>
  <joint name="joint9" type="continuous">
    <origin rpy="0.14692 -0.78569 -1.04079" xyz="-0.0796 -0.03654 0.02721"/>
    <parent link="base_link"/>
    <child link="mcn9"/>
    <axis xyz="1.0 0 0"/>
  </joint>
</robot>
