<?xml version="1.0" ?>
<!-- =================================================================================== -->
<!-- |    This document was autogenerated by xacro from test.urdf.xacro                | -->
<!-- |    EDITING THIS FILE BY HAND IS NOT RECOMMENDED                                 | -->
<!-- =================================================================================== -->
<robot name="roboke">
  <link name="base_link">
    <inertial>
      <origin rpy="0 0 0" xyz="0 0 0"/>
      <mass value="0.5"/>
      <inertia ixx="0.1" ixy="0" ixz="0" iyy="0.1" iyz="0" izz="0.1"/>
    </inertial>
    <visual name="visual_0_base_link">
      <origin rpy="0 0 0" xyz="0 0 0"/>
      <geometry>
        <mesh filename="/home/samet/Desktop/isaac_robomaster/meshes/stl/mecanummain.stl" scale="0.002 0.002 0.002"/>
      </geometry>
    </visual>
    <collision name="collision_0_base_link">
      <origin rpy="0 0 0" xyz="0 0 0"/>
      <geometry>
        <cylinder length="0.08" radius="0.1"/>
      </geometry>
    </collision>
  </link>
  <link name="mcn1">
    <inertial>
      <origin rpy="0 0 0" xyz="0 0 0"/>
      <mass value="0.03"/>
      <inertia ixx="0.1" ixy="0" ixz="0" iyy="0.1" iyz="0" izz="0.1"/>
    </inertial>
    <visual name="visual_0_mcn1">
      <origin rpy="0 0 0" xyz="0 0 0"/>
      <geometry>
        <mesh filename="/home/samet/Desktop/isaac_robomaster/meshes/stl/mecanumroller.stl" scale="0.002 0.002 0.002"/>
      </geometry>
    </visual>
    <collision name="collision_0_mcn1">
      <origin rpy="0 0 0" xyz="0 0 0"/>
      <geometry>
        <mesh filename="/home/samet/Desktop/isaac_robomaster/meshes/stl/mecanumroller.stl" scale="0.002 0.002 0.002"/>
      </geometry>
    </collision>
  </link>
  <link name="mcn10">
    <inertial>
      <origin rpy="0 0 0" xyz="0 0 0"/>
      <mass value="0.03"/>
      <inertia ixx="0.1" ixy="0" ixz="0" iyy="0.1" iyz="0" izz="0.1"/>
    </inertial>
    <visual name="visual_0_mcn10">
      <origin rpy="0 0 0" xyz="0 0 0"/>
      <geometry>
        <mesh filename="/home/samet/Desktop/isaac_robomaster/meshes/stl/mecanumroller.stl" scale="0.002 0.002 0.002"/>
      </geometry>
    </visual>
    <collision name="collision_0_mcn10">
      <origin rpy="0 0 0" xyz="0 0 0"/>
      <geometry>
        <mesh filename="/home/samet/Desktop/isaac_robomaster/meshes/stl/mecanumroller.stl" scale="0.002 0.002 0.002"/>
      </geometry>
    </collision>
  </link>
  <link name="mcn11">
    <inertial>
      <origin rpy="0 0 0" xyz="0 0 0"/>
      <mass value="0.03"/>
      <inertia ixx="0.1" ixy="0" ixz="0" iyy="0.1" iyz="0" izz="0.1"/>
    </inertial>
    <visual name="visual_0_mcn11">
      <origin rpy="0 0 0" xyz="0 0 0"/>
      <geometry>
        <mesh filename="/home/samet/Desktop/isaac_robomaster/meshes/stl/mecanumroller.stl" scale="0.002 0.002 0.002"/>
      </geometry>
    </visual>
    <collision name="collision_0_mcn11">
      <origin rpy="0 0 0" xyz="0 0 0"/>
      <geometry>
        <mesh filename="/home/samet/Desktop/isaac_robomaster/meshes/stl/mecanumroller.stl" scale="0.002 0.002 0.002"/>
      </geometry>
    </collision>
  </link>
  <link name="mcn12">
    <inertial>
      <origin rpy="0 0 0" xyz="0 0 0"/>
      <mass value="0.03"/>
      <inertia ixx="0.1" ixy="0" ixz="0" iyy="0.1" iyz="0" izz="0.1"/>
    </inertial>
    <visual name="visual_0_mcn12">
      <origin rpy="0 0 0" xyz="0 0 0"/>
      <geometry>
        <mesh filename="/home/samet/Desktop/isaac_robomaster/meshes/stl/mecanumroller.stl" scale="0.002 0.002 0.002"/>
      </geometry>
    </visual>
    <collision name="collision_0_mcn12">
      <origin rpy="0 0 0" xyz="0 0 0"/>
      <geometry>
        <mesh filename="/home/samet/Desktop/isaac_robomaster/meshes/stl/mecanumroller.stl" scale="0.002 0.002 0.002"/>
      </geometry>
    </collision>
  </link>
  <link name="mcn2">
    <inertial>
      <origin rpy="0 0 0" xyz="0 0 0"/>
      <mass value="0.03"/>
      <inertia ixx="0.1" ixy="0" ixz="0" iyy="0.1" iyz="0" izz="0.1"/>
    </inertial>
    <visual name="visual_0_mcn2">
      <origin rpy="0 0 0" xyz="0 0 0"/>
      <geometry>
        <mesh filename="/home/samet/Desktop/isaac_robomaster/meshes/stl/mecanumroller.stl" scale="0.002 0.002 0.002"/>
      </geometry>
    </visual>
    <collision name="collision_0_mcn2">
      <origin rpy="0 0 0" xyz="0 0 0"/>
      <geometry>
        <mesh filename="/home/samet/Desktop/isaac_robomaster/meshes/stl/mecanumroller.stl" scale="0.002 0.002 0.002"/>
      </geometry>
    </collision>
  </link>
  <link name="mcn3">
    <inertial>
      <origin rpy="0 0 0" xyz="0 0 0"/>
      <mass value="0.03"/>
      <inertia ixx="0.1" ixy="0" ixz="0" iyy="0.1" iyz="0" izz="0.1"/>
    </inertial>
    <visual name="visual_0_mcn3">
      <origin rpy="0 0 0" xyz="0 0 0"/>
      <geometry>
        <mesh filename="/home/samet/Desktop/isaac_robomaster/meshes/stl/mecanumroller.stl" scale="0.002 0.002 0.002"/>
      </geometry>
    </visual>
    <collision name="collision_0_mcn3">
      <origin rpy="0 0 0" xyz="0 0 0"/>
      <geometry>
        <mesh filename="/home/samet/Desktop/isaac_robomaster/meshes/stl/mecanumroller.stl" scale="0.002 0.002 0.002"/>
      </geometry>
    </collision>
  </link>
  <link name="mcn4">
    <inertial>
      <origin rpy="0 0 0" xyz="0 0 0"/>
      <mass value="0.03"/>
      <inertia ixx="0.1" ixy="0" ixz="0" iyy="0.1" iyz="0" izz="0.1"/>
    </inertial>
    <visual name="visual_0_mcn4">
      <origin rpy="0 0 0" xyz="0 0 0"/>
      <geometry>
        <mesh filename="/home/samet/Desktop/isaac_robomaster/meshes/stl/mecanumroller.stl" scale="0.002 0.002 0.002"/>
      </geometry>
    </visual>
    <collision name="collision_0_mcn4">
      <origin rpy="0 0 0" xyz="0 0 0"/>
      <geometry>
        <mesh filename="/home/samet/Desktop/isaac_robomaster/meshes/stl/mecanumroller.stl" scale="0.002 0.002 0.002"/>
      </geometry>
    </collision>
  </link>
  <link name="mcn5">
    <inertial>
      <origin rpy="0 0 0" xyz="0 0 0"/>
      <mass value="0.03"/>
      <inertia ixx="0.1" ixy="0" ixz="0" iyy="0.1" iyz="0" izz="0.1"/>
    </inertial>
    <visual name="visual_0_mcn5">
      <origin rpy="0 0 0" xyz="0 0 0"/>
      <geometry>
        <mesh filename="/home/samet/Desktop/isaac_robomaster/meshes/stl/mecanumroller.stl" scale="0.002 0.002 0.002"/>
      </geometry>
    </visual>
    <collision name="collision_0_mcn5">
      <origin rpy="0 0 0" xyz="0 0 0"/>
      <geometry>
        <mesh filename="/home/samet/Desktop/isaac_robomaster/meshes/stl/mecanumroller.stl" scale="0.002 0.002 0.002"/>
      </geometry>
    </collision>
  </link>
  <link name="mcn6">
    <inertial>
      <origin rpy="0 0 0" xyz="0 0 0"/>
      <mass value="0.03"/>
      <inertia ixx="0.1" ixy="0" ixz="0" iyy="0.1" iyz="0" izz="0.1"/>
    </inertial>
    <visual name="visual_0_mcn6">
      <origin rpy="0 0 0" xyz="0 0 0"/>
      <geometry>
        <mesh filename="/home/samet/Desktop/isaac_robomaster/meshes/stl/mecanumroller.stl" scale="0.002 0.002 0.002"/>
      </geometry>
    </visual>
    <collision name="collision_0_mcn6">
      <origin rpy="0 0 0" xyz="0 0 0"/>
      <geometry>
        <mesh filename="/home/samet/Desktop/isaac_robomaster/meshes/stl/mecanumroller.stl" scale="0.002 0.002 0.002"/>
      </geometry>
    </collision>
  </link>
  <link name="mcn7">
    <inertial>
      <origin rpy="0 0 0" xyz="0 0 0"/>
      <mass value="0.03"/>
      <inertia ixx="0.1" ixy="0" ixz="0" iyy="0.1" iyz="0" izz="0.1"/>
    </inertial>
    <visual name="visual_0_mcn7">
      <origin rpy="0 0 0" xyz="0 0 0"/>
      <geometry>
        <mesh filename="/home/samet/Desktop/isaac_robomaster/meshes/stl/mecanumroller.stl" scale="0.002 0.002 0.002"/>
      </geometry>
    </visual>
    <collision name="collision_0_mcn7">
      <origin rpy="0 0 0" xyz="0 0 0"/>
      <geometry>
        <mesh filename="/home/samet/Desktop/isaac_robomaster/meshes/stl/mecanumroller.stl" scale="0.002 0.002 0.002"/>
      </geometry>
    </collision>
  </link>
  <link name="mcn8">
    <inertial>
      <origin rpy="0 0 0" xyz="0 0 0"/>
      <mass value="0.03"/>
      <inertia ixx="0.1" ixy="0" ixz="0" iyy="0.1" iyz="0" izz="0.1"/>
    </inertial>
    <visual name="visual_0_mcn8">
      <origin rpy="0 0 0" xyz="0 0 0"/>
      <geometry>
        <mesh filename="/home/samet/Desktop/isaac_robomaster/meshes/stl/mecanumroller.stl" scale="0.002 0.002 0.002"/>
      </geometry>
    </visual>
    <collision name="collision_0_mcn8">
      <origin rpy="0 0 0" xyz="0 0 0"/>
      <geometry>
        <mesh filename="/home/samet/Desktop/isaac_robomaster/meshes/stl/mecanumroller.stl" scale="0.002 0.002 0.002"/>
      </geometry>
    </collision>
  </link>
  <link name="mcn9">
    <inertial>
      <origin rpy="0 0 0" xyz="0 0 0"/>
      <mass value="0.03"/>
      <inertia ixx="0.1" ixy="0" ixz="0" iyy="0.1" iyz="0" izz="0.1"/>
    </inertial>
    <visual name="visual_0_mcn9">
      <origin rpy="0 0 0" xyz="0 0 0"/>
      <geometry>
        <mesh filename="/home/samet/Desktop/isaac_robomaster/meshes/stl/mecanumroller.stl" scale="0.002 0.002 0.002"/>
      </geometry>
    </visual>
    <collision name="collision_0_mcn9">
      <origin rpy="0 0 0" xyz="0 0 0"/>
      <geometry>
        <mesh filename="/home/samet/Desktop/isaac_robomaster/meshes/stl/mecanumroller.stl" scale="0.002 0.002 0.002"/>
      </geometry>
    </collision>
  </link>
  <joint name="joint1" type="continuous">
    <origin rpy="-1.76186 -0.79552 1.05175" xyz="0.07167 -0.05076 0.02846"/>
    <parent link="base_link"/>
    <child link="mcn1"/>
    <axis xyz="1.0 0 0"/>
  </joint>
  <joint name="joint10" type="continuous">
    <origin rpy="0.5806 -0.79466 -0.51932" xyz="-0.05038 -0.07171 0.02782"/>
    <parent link="base_link"/>
    <child link="mcn10"/>
    <axis xyz="1.0 0 0"/>
  </joint>
  <joint name="joint11" type="continuous">
    <origin rpy="0.10036 -0.79327 0.03137" xyz="-0.00767 -0.08779 0.02845"/>
    <parent link="base_link"/>
    <child link="mcn11"/>
    <axis xyz="1.0 0 0"/>
  </joint>
  <joint name="joint12" type="continuous">
    <origin rpy="0.75677 -0.79045 0.52668" xyz="0.03673 -0.07863 0.02825"/>
    <parent link="base_link"/>
    <child link="mcn12"/>
    <axis xyz="1.0 0 0"/>
  </joint>
  <joint name="joint2" type="continuous">
    <origin rpy="0.83828 -0.82486 1.56595" xyz="0.0864 -0.00753 0.02879"/>
    <parent link="base_link"/>
    <child link="mcn2"/>
    <axis xyz="1.0 0 0"/>
  </joint>
  <joint name="joint3" type="continuous">
    <origin rpy="-0.91674 -0.80295 2.13129" xyz="0.08054 0.03653 0.02804"/>
    <parent link="base_link"/>
    <child link="mcn3"/>
    <axis xyz="1.0 0 0"/>
  </joint>
  <joint name="joint4" type="continuous">
    <origin rpy="-0.10837 -2.34403 -0.53781" xyz="0.05184 0.06967 0.02692"/>
    <parent link="base_link"/>
    <child link="mcn4"/>
    <axis xyz="1.0 0 0"/>
  </joint>
  <joint name="joint5" type="continuous">
    <origin rpy="0.16079 -2.35154 0.00616" xyz="0.00816 0.08667 0.02858"/>
    <parent link="base_link"/>
    <child link="mcn5"/>
    <axis xyz="1.0 0 0"/>
  </joint>
  <joint name="joint6" type="continuous">
    <origin rpy="-0.75572 -2.34708 1.04931" xyz="-0.07119 0.05132 0.02734"/>
    <parent link="base_link"/>
    <child link="mcn6"/>
    <axis xyz="1.0 0 0"/>
  </joint>
  <joint name="joint7" type="continuous">
    <origin rpy="-1.06708 -2.36432 0.51602" xyz="-0.03617 0.07901 0.0277"/>
    <parent link="base_link"/>
    <child link="mcn7"/>
    <axis xyz="1.0 0 0"/>
  </joint>
  <joint name="joint8" type="continuous">
    <origin rpy="1.5226 -0.80215 -1.58604" xyz="-0.08659 0.00832 0.02734"/>
    <parent link="base_link"/>
    <child link="mcn8"/>
    <axis xyz="1.0 0 0"/>
  </joint>
  <joint name="joint9" type="continuous">
    <origin rpy="0.14692 -0.78569 -1.04079" xyz="-0.0796 -0.03654 0.02721"/>
    <parent link="base_link"/>
    <child link="mcn9"/>
    <axis xyz="1.0 0 0"/>
  </joint>
  <link name="base_link2">
    <inertial>
      <origin rpy="0 0 0" xyz="0 0 0"/>
      <mass value="0.5"/>
      <inertia ixx="0.1" ixy="0" ixz="0" iyy="0.1" iyz="0" izz="0.1"/>
    </inertial>
    <visual>
      <origin rpy="0 0 0" xyz="0 0 0"/>
      <geometry>
        <mesh filename="/home/samet/Desktop/isaac_robomaster/meshes/stl/mecanummain.stl" scale="0.002 0.002 0.002"/>
      </geometry>
    </visual>
    <collision>
      <origin rpy="0 0 0" xyz="0 0 0"/>
      <geometry>
        <cylinder length="0.08" radius="0.1"/>
      </geometry>
    </collision>
  </link>
  <link name="mcnN1">
    <inertial>
      <origin rpy="0 0 0" xyz="0 0 0"/>
      <mass value="0.03"/>
      <inertia ixx="0.1" ixy="0" ixz="0" iyy="0.1" iyz="0" izz="0.1"/>
    </inertial>
    <visual>
      <origin rpy="0 0 0" xyz="0 0 0"/>
      <geometry>
        <mesh filename="/home/samet/Desktop/isaac_robomaster/meshes/stl/mecanumroller.stl" scale="0.002 0.002 0.002"/>
      </geometry>
    </visual>
    <collision>
      <origin rpy="0 0 0" xyz="0 0 0"/>
      <geometry>
        <mesh filename="/home/samet/Desktop/isaac_robomaster/meshes/stl/mecanumroller.stl" scale="0.002 0.002 0.002"/>
      </geometry>
    </collision>
  </link>
  <link name="mcnN10">
    <inertial>
      <origin rpy="0 0 0" xyz="0 0 0"/>
      <mass value="0.03"/>
      <inertia ixx="0.1" ixy="0" ixz="0" iyy="0.1" iyz="0" izz="0.1"/>
    </inertial>
    <visual>
      <origin rpy="0 0 0" xyz="0 0 0"/>
      <geometry>
        <mesh filename="/home/samet/Desktop/isaac_robomaster/meshes/stl/mecanumroller.stl" scale="0.002 0.002 0.002"/>
      </geometry>
    </visual>
    <collision>
      <origin rpy="0 0 0" xyz="0 0 0"/>
      <geometry>
        <mesh filename="/home/samet/Desktop/isaac_robomaster/meshes/stl/mecanumroller.stl" scale="0.002 0.002 0.002"/>
      </geometry>
    </collision>
  </link>
  <link name="mcnN11">
    <inertial>
      <origin rpy="0 0 0" xyz="0 0 0"/>
      <mass value="0.03"/>
      <inertia ixx="0.1" ixy="0" ixz="0" iyy="0.1" iyz="0" izz="0.1"/>
    </inertial>
    <visual>
      <origin rpy="0 0 0" xyz="0 0 0"/>
      <geometry>
        <mesh filename="/home/samet/Desktop/isaac_robomaster/meshes/stl/mecanumroller.stl" scale="0.002 0.002 0.002"/>
      </geometry>
    </visual>
    <collision>
      <origin rpy="0 0 0" xyz="0 0 0"/>
      <geometry>
        <mesh filename="/home/samet/Desktop/isaac_robomaster/meshes/stl/mecanumroller.stl" scale="0.002 0.002 0.002"/>
      </geometry>
    </collision>
  </link>
  <link name="mcnN12">
    <inertial>
      <origin rpy="0 0 0" xyz="0 0 0"/>
      <mass value="0.03"/>
      <inertia ixx="0.1" ixy="0" ixz="0" iyy="0.1" iyz="0" izz="0.1"/>
    </inertial>
    <visual>
      <origin rpy="0 0 0" xyz="0 0 0"/>
      <geometry>
        <mesh filename="/home/samet/Desktop/isaac_robomaster/meshes/stl/mecanumroller.stl" scale="0.002 0.002 0.002"/>
      </geometry>
    </visual>
    <collision>
      <origin rpy="0 0 0" xyz="0 0 0"/>
      <geometry>
        <mesh filename="/home/samet/Desktop/isaac_robomaster/meshes/stl/mecanumroller.stl" scale="0.002 0.002 0.002"/>
      </geometry>
    </collision>
  </link>
  <link name="mcnN2">
    <inertial>
      <origin rpy="0 0 0" xyz="0 0 0"/>
      <mass value="0.03"/>
      <inertia ixx="0.1" ixy="0" ixz="0" iyy="0.1" iyz="0" izz="0.1"/>
    </inertial>
    <visual>
      <origin rpy="0 0 0" xyz="0 0 0"/>
      <geometry>
        <mesh filename="/home/samet/Desktop/isaac_robomaster/meshes/stl/mecanumroller.stl" scale="0.002 0.002 0.002"/>
      </geometry>
    </visual>
    <collision>
      <origin rpy="0 0 0" xyz="0 0 0"/>
      <geometry>
        <mesh filename="/home/samet/Desktop/isaac_robomaster/meshes/stl/mecanumroller.stl" scale="0.002 0.002 0.002"/>
      </geometry>
    </collision>
  </link>
  <link name="mcnN3">
    <inertial>
      <origin rpy="0 0 0" xyz="0 0 0"/>
      <mass value="0.03"/>
      <inertia ixx="0.1" ixy="0" ixz="0" iyy="0.1" iyz="0" izz="0.1"/>
    </inertial>
    <visual>
      <origin rpy="0 0 0" xyz="0 0 0"/>
      <geometry>
        <mesh filename="/home/samet/Desktop/isaac_robomaster/meshes/stl/mecanumroller.stl" scale="0.002 0.002 0.002"/>
      </geometry>
    </visual>
    <collision>
      <origin rpy="0 0 0" xyz="0 0 0"/>
      <geometry>
        <mesh filename="/home/samet/Desktop/isaac_robomaster/meshes/stl/mecanumroller.stl" scale="0.002 0.002 0.002"/>
      </geometry>
    </collision>
  </link>
  <link name="mcnN4">
    <inertial>
      <origin rpy="0 0 0" xyz="0 0 0"/>
      <mass value="0.03"/>
      <inertia ixx="0.1" ixy="0" ixz="0" iyy="0.1" iyz="0" izz="0.1"/>
    </inertial>
    <visual>
      <origin rpy="0 0 0" xyz="0 0 0"/>
      <geometry>
        <mesh filename="/home/samet/Desktop/isaac_robomaster/meshes/stl/mecanumroller.stl" scale="0.002 0.002 0.002"/>
      </geometry>
    </visual>
    <collision>
      <origin rpy="0 0 0" xyz="0 0 0"/>
      <geometry>
        <mesh filename="/home/samet/Desktop/isaac_robomaster/meshes/stl/mecanumroller.stl" scale="0.002 0.002 0.002"/>
      </geometry>
    </collision>
  </link>
  <link name="mcnN5">
    <inertial>
      <origin rpy="0 0 0" xyz="0 0 0"/>
      <mass value="0.03"/>
      <inertia ixx="0.1" ixy="0" ixz="0" iyy="0.1" iyz="0" izz="0.1"/>
    </inertial>
    <visual>
      <origin rpy="0 0 0" xyz="0 0 0"/>
      <geometry>
        <mesh filename="/home/samet/Desktop/isaac_robomaster/meshes/stl/mecanumroller.stl" scale="0.002 0.002 0.002"/>
      </geometry>
    </visual>
    <collision>
      <origin rpy="0 0 0" xyz="0 0 0"/>
      <geometry>
        <mesh filename="/home/samet/Desktop/isaac_robomaster/meshes/stl/mecanumroller.stl" scale="0.002 0.002 0.002"/>
      </geometry>
    </collision>
  </link>
  <link name="mcnN6">
    <inertial>
      <origin rpy="0 0 0" xyz="0 0 0"/>
      <mass value="0.03"/>
      <inertia ixx="0.1" ixy="0" ixz="0" iyy="0.1" iyz="0" izz="0.1"/>
    </inertial>
    <visual>
      <origin rpy="0 0 0" xyz="0 0 0"/>
      <geometry>
        <mesh filename="/home/samet/Desktop/isaac_robomaster/meshes/stl/mecanumroller.stl" scale="0.002 0.002 0.002"/>
      </geometry>
    </visual>
    <collision>
      <origin rpy="0 0 0" xyz="0 0 0"/>
      <geometry>
        <mesh filename="/home/samet/Desktop/isaac_robomaster/meshes/stl/mecanumroller.stl" scale="0.002 0.002 0.002"/>
      </geometry>
    </collision>
  </link>
  <link name="mcnN7">
    <inertial>
      <origin rpy="0 0 0" xyz="0 0 0"/>
      <mass value="0.03"/>
      <inertia ixx="0.1" ixy="0" ixz="0" iyy="0.1" iyz="0" izz="0.1"/>
    </inertial>
    <visual>
      <origin rpy="0 0 0" xyz="0 0 0"/>
      <geometry>
        <mesh filename="/home/samet/Desktop/isaac_robomaster/meshes/stl/mecanumroller.stl" scale="0.002 0.002 0.002"/>
      </geometry>
    </visual>
    <collision>
      <origin rpy="0 0 0" xyz="0 0 0"/>
      <geometry>
        <mesh filename="/home/samet/Desktop/isaac_robomaster/meshes/stl/mecanumroller.stl" scale="0.002 0.002 0.002"/>
      </geometry>
    </collision>
  </link>
  <link name="mcnN8">
    <inertial>
      <origin rpy="0 0 0" xyz="0 0 0"/>
      <mass value="0.03"/>
      <inertia ixx="0.1" ixy="0" ixz="0" iyy="0.1" iyz="0" izz="0.1"/>
    </inertial>
    <visual>
      <origin rpy="0 0 0" xyz="0 0 0"/>
      <geometry>
        <mesh filename="/home/samet/Desktop/isaac_robomaster/meshes/stl/mecanumroller.stl" scale="0.002 0.002 0.002"/>
      </geometry>
    </visual>
    <collision>
      <origin rpy="0 0 0" xyz="0 0 0"/>
      <geometry>
        <mesh filename="/home/samet/Desktop/isaac_robomaster/meshes/stl/mecanumroller.stl" scale="0.002 0.002 0.002"/>
      </geometry>
    </collision>
  </link>
  <link name="mcnN9">
    <inertial>
      <origin rpy="0 0 0" xyz="0 0 0"/>
      <mass value="0.03"/>
      <inertia ixx="0.1" ixy="0" ixz="0" iyy="0.1" iyz="0" izz="0.1"/>
    </inertial>
    <visual>
      <origin rpy="0 0 0" xyz="0 0 0"/>
      <geometry>
        <mesh filename="/home/samet/Desktop/isaac_robomaster/meshes/stl/mecanumroller.stl" scale="0.002 0.002 0.002"/>
      </geometry>
    </visual>
    <collision>
      <origin rpy="0 0 0" xyz="0 0 0"/>
      <geometry>
        <mesh filename="/home/samet/Desktop/isaac_robomaster/meshes/stl/mecanumroller.stl" scale="0.002 0.002 0.002"/>
      </geometry>
    </collision>
  </link>
  <joint name="jjoint1" type="continuous">
    <origin rpy="-1.76186 -0.79552 1.05175" xyz="0.07167 -0.05076 0.02846"/>
    <parent link="base_link2"/>
    <child link="mcnN1"/>
    <axis xyz="1.0 0 0"/>
  </joint>
  <joint name="jjoint10" type="continuous">
    <origin rpy="0.5806 -0.79466 -0.51932" xyz="-0.05038 -0.07171 0.02782"/>
    <parent link="base_link2"/>
    <child link="mcnN10"/>
    <axis xyz="1.0 0 0"/>
  </joint>
  <joint name="jjoint11" type="continuous">
    <origin rpy="0.10036 -0.79327 0.03137" xyz="-0.00767 -0.08779 0.02845"/>
    <parent link="base_link2"/>
    <child link="mcnN11"/>
    <axis xyz="1.0 0 0"/>
  </joint>
  <joint name="jjoint12" type="continuous">
    <origin rpy="0.75677 -0.79045 0.52668" xyz="0.03673 -0.07863 0.02825"/>
    <parent link="base_link2"/>
    <child link="mcnN12"/>
    <axis xyz="1.0 0 0"/>
  </joint>
  <joint name="jjoint2" type="continuous">
    <origin rpy="0.83828 -0.82486 1.56595" xyz="0.0864 -0.00753 0.02879"/>
    <parent link="base_link2"/>
    <child link="mcnN2"/>
    <axis xyz="1.0 0 0"/>
  </joint>
  <joint name="jjoint3" type="continuous">
    <origin rpy="-0.91674 -0.80295 2.13129" xyz="0.08054 0.03653 0.02804"/>
    <parent link="base_link2"/>
    <child link="mcnN3"/>
    <axis xyz="1.0 0 0"/>
  </joint>
  <joint name="jjoint4" type="continuous">
    <origin rpy="-0.10837 -2.34403 -0.53781" xyz="0.05184 0.06967 0.02692"/>
    <parent link="base_link2"/>
    <child link="mcnN4"/>
    <axis xyz="1.0 0 0"/>
  </joint>
  <joint name="jjoint5" type="continuous">
    <origin rpy="0.16079 -2.35154 0.00616" xyz="0.00816 0.08667 0.02858"/>
    <parent link="base_link2"/>
    <child link="mcnN5"/>
    <axis xyz="1.0 0 0"/>
  </joint>
  <joint name="jjoint6" type="continuous">
    <origin rpy="-0.75572 -2.34708 1.04931" xyz="-0.07119 0.05132 0.02734"/>
    <parent link="base_link2"/>
    <child link="mcnN6"/>
    <axis xyz="1.0 0 0"/>
  </joint>
  <joint name="jjoint7" type="continuous">
    <origin rpy="-1.06708 -2.36432 0.51602" xyz="-0.03617 0.07901 0.0277"/>
    <parent link="base_link2"/>
    <child link="mcnN7"/>
    <axis xyz="1.0 0 0"/>
  </joint>
  <joint name="jjoint8" type="continuous">
    <origin rpy="1.5226 -0.80215 -1.58604" xyz="-0.08659 0.00832 0.02734"/>
    <parent link="base_link2"/>
    <child link="mcnN8"/>
    <axis xyz="1.0 0 0"/>
  </joint>
  <joint name="jjoint9" type="continuous">
    <origin rpy="0.14692 -0.78569 -1.04079" xyz="-0.0796 -0.03654 0.02721"/>
    <parent link="base_link2"/>
    <child link="mcnN9"/>
    <axis xyz="1.0 0 0"/>
  </joint>
  <link name="base_link3">
    <inertial>
      <origin rpy="0 0 0" xyz="0 0 0"/>
      <mass value="0.5"/>
      <inertia ixx="0.1" ixy="0" ixz="0" iyy="0.1" iyz="0" izz="0.1"/>
    </inertial>
    <visual>
      <origin rpy="0 0 0" xyz="0 0 0"/>
      <geometry>
        <mesh filename="/home/samet/Desktop/robomaster-stl-files/wheels/mecanumcenter2.stl" scale="0.002 0.002 0.002"/>
      </geometry>
    </visual>
    <collision>
      <origin rpy="0 0 0" xyz="0 0 0"/>
      <geometry>
        <cylinder length="0.08" radius="0.1"/>
      </geometry>
    </collision>
  </link>
  <link name="mcnNArka1">
    <inertial>
      <origin rpy="0 0 0" xyz="0 0 0"/>
      <mass value="0.03"/>
      <inertia ixx="0.1" ixy="0" ixz="0" iyy="0.1" iyz="0" izz="0.1"/>
    </inertial>
    <visual>
      <origin rpy="0 0 0" xyz="0 0 0"/>
      <geometry>
        <mesh filename="/home/samet/Desktop/robomaster-stl-files/wheels/mecanumroller.stl" scale="0.002 0.002 0.002"/>
      </geometry>
    </visual>
    <collision>
      <origin rpy="0 0 0" xyz="0 0 0"/>
      <geometry>
        <mesh filename="/home/samet/Desktop/robomaster-stl-files/wheels/mecanumroller.stl" scale="0.002 0.002 0.002"/>
      </geometry>
    </collision>
  </link>
  <link name="mcnNArka10">
    <inertial>
      <origin rpy="0 0 0" xyz="0 0 0"/>
      <mass value="0.03"/>
      <inertia ixx="0.1" ixy="0" ixz="0" iyy="0.1" iyz="0" izz="0.1"/>
    </inertial>
    <visual>
      <origin rpy="0 0 0" xyz="0 0 0"/>
      <geometry>
        <mesh filename="/home/samet/Desktop/robomaster-stl-files/wheels/mecanumroller.stl" scale="0.002 0.002 0.002"/>
      </geometry>
    </visual>
    <collision>
      <origin rpy="0 0 0" xyz="0 0 0"/>
      <geometry>
        <mesh filename="/home/samet/Desktop/robomaster-stl-files/wheels/mecanumroller.stl" scale="0.002 0.002 0.002"/>
      </geometry>
    </collision>
  </link>
  <link name="mcnNArka11">
    <inertial>
      <origin rpy="0 0 0" xyz="0 0 0"/>
      <mass value="0.03"/>
      <inertia ixx="0.1" ixy="0" ixz="0" iyy="0.1" iyz="0" izz="0.1"/>
    </inertial>
    <visual>
      <origin rpy="0 0 0" xyz="0 0 0"/>
      <geometry>
        <mesh filename="/home/samet/Desktop/robomaster-stl-files/wheels/mecanumroller.stl" scale="0.002 0.002 0.002"/>
      </geometry>
    </visual>
    <collision>
      <origin rpy="0 0 0" xyz="0 0 0"/>
      <geometry>
        <mesh filename="/home/samet/Desktop/robomaster-stl-files/wheels/mecanumroller.stl" scale="0.002 0.002 0.002"/>
      </geometry>
    </collision>
  </link>
  <link name="mcnNArka12">
    <inertial>
      <origin rpy="0 0 0" xyz="0 0 0"/>
      <mass value="0.03"/>
      <inertia ixx="0.1" ixy="0" ixz="0" iyy="0.1" iyz="0" izz="0.1"/>
    </inertial>
    <visual>
      <origin rpy="0 0 0" xyz="0 0 0"/>
      <geometry>
        <mesh filename="/home/samet/Desktop/robomaster-stl-files/wheels/mecanumroller.stl" scale="0.002 0.002 0.002"/>
      </geometry>
    </visual>
    <collision>
      <origin rpy="0 0 0" xyz="0 0 0"/>
      <geometry>
        <mesh filename="/home/samet/Desktop/robomaster-stl-files/wheels/mecanumroller.stl" scale="0.002 0.002 0.002"/>
      </geometry>
    </collision>
  </link>
  <link name="mcnNArka2">
    <inertial>
      <origin rpy="0 0 0" xyz="0 0 0"/>
      <mass value="0.03"/>
      <inertia ixx="0.1" ixy="0" ixz="0" iyy="0.1" iyz="0" izz="0.1"/>
    </inertial>
    <visual>
      <origin rpy="0 0 0" xyz="0 0 0"/>
      <geometry>
        <mesh filename="/home/samet/Desktop/robomaster-stl-files/wheels/mecanumroller.stl" scale="0.002 0.002 0.002"/>
      </geometry>
    </visual>
    <collision>
      <origin rpy="0 0 0" xyz="0 0 0"/>
      <geometry>
        <mesh filename="/home/samet/Desktop/robomaster-stl-files/wheels/mecanumroller.stl" scale="0.002 0.002 0.002"/>
      </geometry>
    </collision>
  </link>
  <link name="mcnNArka3">
    <inertial>
      <origin rpy="0 0 0" xyz="0 0 0"/>
      <mass value="0.03"/>
      <inertia ixx="0.1" ixy="0" ixz="0" iyy="0.1" iyz="0" izz="0.1"/>
    </inertial>
    <visual>
      <origin rpy="0 0 0" xyz="0 0 0"/>
      <geometry>
        <mesh filename="/home/samet/Desktop/robomaster-stl-files/wheels/mecanumroller.stl" scale="0.002 0.002 0.002"/>
      </geometry>
    </visual>
    <collision>
      <origin rpy="0 0 0" xyz="0 0 0"/>
      <geometry>
        <mesh filename="/home/samet/Desktop/robomaster-stl-files/wheels/mecanumroller.stl" scale="0.002 0.002 0.002"/>
      </geometry>
    </collision>
  </link>
  <link name="mcnNArka4">
    <inertial>
      <origin rpy="0 0 0" xyz="0 0 0"/>
      <mass value="0.03"/>
      <inertia ixx="0.1" ixy="0" ixz="0" iyy="0.1" iyz="0" izz="0.1"/>
    </inertial>
    <visual>
      <origin rpy="0 0 0" xyz="0 0 0"/>
      <geometry>
        <mesh filename="/home/samet/Desktop/robomaster-stl-files/wheels/mecanumroller.stl" scale="0.002 0.002 0.002"/>
      </geometry>
    </visual>
    <collision>
      <origin rpy="0 0 0" xyz="0 0 0"/>
      <geometry>
        <mesh filename="/home/samet/Desktop/robomaster-stl-files/wheels/mecanumroller.stl" scale="0.002 0.002 0.002"/>
      </geometry>
    </collision>
  </link>
  <link name="mcnNArka5">
    <inertial>
      <origin rpy="0 0 0" xyz="0 0 0"/>
      <mass value="0.03"/>
      <inertia ixx="0.1" ixy="0" ixz="0" iyy="0.1" iyz="0" izz="0.1"/>
    </inertial>
    <visual>
      <origin rpy="0 0 0" xyz="0 0 0"/>
      <geometry>
        <mesh filename="/home/samet/Desktop/robomaster-stl-files/wheels/mecanumroller.stl" scale="0.002 0.002 0.002"/>
      </geometry>
    </visual>
    <collision>
      <origin rpy="0 0 0" xyz="0 0 0"/>
      <geometry>
        <mesh filename="/home/samet/Desktop/robomaster-stl-files/wheels/mecanumroller.stl" scale="0.002 0.002 0.002"/>
      </geometry>
    </collision>
  </link>
  <link name="mcnNArka6">
    <inertial>
      <origin rpy="0 0 0" xyz="0 0 0"/>
      <mass value="0.03"/>
      <inertia ixx="0.1" ixy="0" ixz="0" iyy="0.1" iyz="0" izz="0.1"/>
    </inertial>
    <visual>
      <origin rpy="0 0 0" xyz="0 0 0"/>
      <geometry>
        <mesh filename="/home/samet/Desktop/robomaster-stl-files/wheels/mecanumroller.stl" scale="0.002 0.002 0.002"/>
      </geometry>
    </visual>
    <collision>
      <origin rpy="0 0 0" xyz="0 0 0"/>
      <geometry>
        <mesh filename="/home/samet/Desktop/robomaster-stl-files/wheels/mecanumroller.stl" scale="0.002 0.002 0.002"/>
      </geometry>
    </collision>
  </link>
  <link name="mcnNArka7">
    <inertial>
      <origin rpy="0 0 0" xyz="0 0 0"/>
      <mass value="0.03"/>
      <inertia ixx="0.1" ixy="0" ixz="0" iyy="0.1" iyz="0" izz="0.1"/>
    </inertial>
    <visual>
      <origin rpy="0 0 0" xyz="0 0 0"/>
      <geometry>
        <mesh filename="/home/samet/Desktop/robomaster-stl-files/wheels/mecanumroller.stl" scale="0.002 0.002 0.002"/>
      </geometry>
    </visual>
    <collision>
      <origin rpy="0 0 0" xyz="0 0 0"/>
      <geometry>
        <mesh filename="/home/samet/Desktop/robomaster-stl-files/wheels/mecanumroller.stl" scale="0.002 0.002 0.002"/>
      </geometry>
    </collision>
  </link>
  <link name="mcnNArka8">
    <inertial>
      <origin rpy="0 0 0" xyz="0 0 0"/>
      <mass value="0.03"/>
      <inertia ixx="0.1" ixy="0" ixz="0" iyy="0.1" iyz="0" izz="0.1"/>
    </inertial>
    <visual>
      <origin rpy="0 0 0" xyz="0 0 0"/>
      <geometry>
        <mesh filename="/home/samet/Desktop/robomaster-stl-files/wheels/mecanumroller.stl" scale="0.002 0.002 0.002"/>
      </geometry>
    </visual>
    <collision>
      <origin rpy="0 0 0" xyz="0 0 0"/>
      <geometry>
        <mesh filename="/home/samet/Desktop/robomaster-stl-files/wheels/mecanumroller.stl" scale="0.002 0.002 0.002"/>
      </geometry>
    </collision>
  </link>
  <link name="mcnNArka9">
    <inertial>
      <origin rpy="0 0 0" xyz="0 0 0"/>
      <mass value="0.03"/>
      <inertia ixx="0.1" ixy="0" ixz="0" iyy="0.1" iyz="0" izz="0.1"/>
    </inertial>
    <visual>
      <origin rpy="0 0 0" xyz="0 0 0"/>
      <geometry>
        <mesh filename="/home/samet/Desktop/robomaster-stl-files/wheels/mecanumroller.stl" scale="0.002 0.002 0.002"/>
      </geometry>
    </visual>
    <collision>
      <origin rpy="0 0 0" xyz="0 0 0"/>
      <geometry>
        <mesh filename="/home/samet/Desktop/robomaster-stl-files/wheels/mecanumroller.stl" scale="0.002 0.002 0.002"/>
      </geometry>
    </collision>
  </link>
  <joint name="jjjoint1" type="continuous">
    <origin rpy="1.69616 -0.78865 -2.09076" xyz="0.08098 -0.03389 0.02632"/>
    <parent link="base_link3"/>
    <child link="mcnNArka1"/>
    <axis xyz="1.0 0 0"/>
  </joint>
  <joint name="jjjoint10" type="continuous">
    <origin rpy="0.16809 -2.34167 -0.52068" xyz="-0.03447 -0.08054 0.02726"/>
    <parent link="base_link3"/>
    <child link="mcnNArka10"/>
    <axis xyz="1.0 0 0"/>
  </joint>
  <joint name="jjjoint11" type="continuous">
    <origin rpy="0.20837 -2.34561 -0.00054" xyz="0.01035 -0.08714 0.02744"/>
    <parent link="base_link3"/>
    <child link="mcnNArka11"/>
    <axis xyz="1.0 0 0"/>
  </joint>
  <joint name="jjjoint12" type="continuous">
    <origin rpy="1.39158 -2.3543 0.52842" xyz="0.05215 -0.0703 0.02768"/>
    <parent link="base_link3"/>
    <child link="mcnNArka12"/>
    <axis xyz="1.0 0 0"/>
  </joint>
  <joint name="jjjoint2" type="continuous">
    <origin rpy="0.15693 -2.35442 1.57268" xyz="0.08702 0.01083 0.02674"/>
    <parent link="base_link3"/>
    <child link="mcnNArka2"/>
    <axis xyz="1.0 0 0"/>
  </joint>
  <joint name="jjjoint3" type="continuous">
    <origin rpy="1.99732 -0.78629 -1.0356" xyz="0.07027 0.0522 0.02725"/>
    <parent link="base_link3"/>
    <child link="mcnNArka3"/>
    <axis xyz="1.0 0 0"/>
  </joint>
  <joint name="jjjoint4" type="continuous">
    <origin rpy="-0.01116 -0.78641 -0.52158" xyz="0.03408 0.08081 0.02656"/>
    <parent link="base_link3"/>
    <child link="mcnNArka4"/>
    <axis xyz="1.0 0 0"/>
  </joint>
  <joint name="jjjoint5" type="continuous">
    <origin rpy="0.22604 -0.78465 0.00764" xyz="-0.00989 0.08688 0.02757"/>
    <parent link="base_link3"/>
    <child link="mcnNArka5"/>
    <axis xyz="1.0 0 0"/>
  </joint>
  <joint name="jjjoint6" type="continuous">
    <origin rpy="-0.92993 -0.78212 1.05974" xyz="-0.07998 0.03542 0.02784"/>
    <parent link="base_link3"/>
    <child link="mcnNArka6"/>
    <axis xyz="1.0 0 0"/>
  </joint>
  <joint name="jjjoint7" type="continuous">
    <origin rpy="-1.87163 -0.79217 0.5363" xyz="-0.05165 0.0708 0.02816"/>
    <parent link="base_link3"/>
    <child link="mcnNArka7"/>
    <axis xyz="1.0 0 0"/>
  </joint>
  <joint name="jjjoint8" type="continuous">
    <origin rpy="-1.50807 -0.79738 1.59404" xyz="-0.08668 -0.00986 0.02799"/>
    <parent link="base_link3"/>
    <child link="mcnNArka8"/>
    <axis xyz="1.0 0 0"/>
  </joint>
  <joint name="jjjoint9" type="continuous">
    <origin rpy="0.95433 -2.33443 -1.04334" xyz="-0.07027 -0.0525 0.02729"/>
    <parent link="base_link3"/>
    <child link="mcnNArka9"/>
    <axis xyz="1.0 0 0"/>
  </joint>
  <link name="base_link4">
    <inertial>
      <origin rpy="0 0 0" xyz="0 0 0"/>
      <mass value="0.5"/>
      <inertia ixx="0.1" ixy="0" ixz="0" iyy="0.1" iyz="0" izz="0.1"/>
    </inertial>
    <visual>
      <origin rpy="0 0 0" xyz="0 0 0"/>
      <geometry>
        <mesh filename="/home/samet/Desktop/robomaster-stl-files/wheels/mecanumcenter2.stl" scale="0.002 0.002 0.002"/>
      </geometry>
    </visual>
    <collision>
      <origin rpy="0 0 0" xyz="0 0 0"/>
      <geometry>
        <cylinder length="0.08" radius="0.1"/>
      </geometry>
    </collision>
  </link>
  <link name="mcnNNArka1">
    <inertial>
      <origin rpy="0 0 0" xyz="0 0 0"/>
      <mass value="0.03"/>
      <inertia ixx="0.1" ixy="0" ixz="0" iyy="0.1" iyz="0" izz="0.1"/>
    </inertial>
    <visual>
      <origin rpy="0 0 0" xyz="0 0 0"/>
      <geometry>
        <mesh filename="/home/samet/Desktop/robomaster-stl-files/wheels/mecanumroller.stl" scale="0.002 0.002 0.002"/>
      </geometry>
    </visual>
    <collision>
      <origin rpy="0 0 0" xyz="0 0 0"/>
      <geometry>
        <mesh filename="/home/samet/Desktop/robomaster-stl-files/wheels/mecanumroller.stl" scale="0.002 0.002 0.002"/>
      </geometry>
    </collision>
  </link>
  <link name="mcnNNArka10">
    <inertial>
      <origin rpy="0 0 0" xyz="0 0 0"/>
      <mass value="0.03"/>
      <inertia ixx="0.1" ixy="0" ixz="0" iyy="0.1" iyz="0" izz="0.1"/>
    </inertial>
    <visual>
      <origin rpy="0 0 0" xyz="0 0 0"/>
      <geometry>
        <mesh filename="/home/samet/Desktop/robomaster-stl-files/wheels/mecanumroller.stl" scale="0.002 0.002 0.002"/>
      </geometry>
    </visual>
    <collision>
      <origin rpy="0 0 0" xyz="0 0 0"/>
      <geometry>
        <mesh filename="/home/samet/Desktop/robomaster-stl-files/wheels/mecanumroller.stl" scale="0.002 0.002 0.002"/>
      </geometry>
    </collision>
  </link>
  <link name="mcnNNArka11">
    <inertial>
      <origin rpy="0 0 0" xyz="0 0 0"/>
      <mass value="0.03"/>
      <inertia ixx="0.1" ixy="0" ixz="0" iyy="0.1" iyz="0" izz="0.1"/>
    </inertial>
    <visual>
      <origin rpy="0 0 0" xyz="0 0 0"/>
      <geometry>
        <mesh filename="/home/samet/Desktop/robomaster-stl-files/wheels/mecanumroller.stl" scale="0.002 0.002 0.002"/>
      </geometry>
    </visual>
    <collision>
      <origin rpy="0 0 0" xyz="0 0 0"/>
      <geometry>
        <mesh filename="/home/samet/Desktop/robomaster-stl-files/wheels/mecanumroller.stl" scale="0.002 0.002 0.002"/>
      </geometry>
    </collision>
  </link>
  <link name="mcnNNArka12">
    <inertial>
      <origin rpy="0 0 0" xyz="0 0 0"/>
      <mass value="0.03"/>
      <inertia ixx="0.1" ixy="0" ixz="0" iyy="0.1" iyz="0" izz="0.1"/>
    </inertial>
    <visual>
      <origin rpy="0 0 0" xyz="0 0 0"/>
      <geometry>
        <mesh filename="/home/samet/Desktop/robomaster-stl-files/wheels/mecanumroller.stl" scale="0.002 0.002 0.002"/>
      </geometry>
    </visual>
    <collision>
      <origin rpy="0 0 0" xyz="0 0 0"/>
      <geometry>
        <mesh filename="/home/samet/Desktop/robomaster-stl-files/wheels/mecanumroller.stl" scale="0.002 0.002 0.002"/>
      </geometry>
    </collision>
  </link>
  <link name="mcnNNArka2">
    <inertial>
      <origin rpy="0 0 0" xyz="0 0 0"/>
      <mass value="0.03"/>
      <inertia ixx="0.1" ixy="0" ixz="0" iyy="0.1" iyz="0" izz="0.1"/>
    </inertial>
    <visual>
      <origin rpy="0 0 0" xyz="0 0 0"/>
      <geometry>
        <mesh filename="/home/samet/Desktop/robomaster-stl-files/wheels/mecanumroller.stl" scale="0.002 0.002 0.002"/>
      </geometry>
    </visual>
    <collision>
      <origin rpy="0 0 0" xyz="0 0 0"/>
      <geometry>
        <mesh filename="/home/samet/Desktop/robomaster-stl-files/wheels/mecanumroller.stl" scale="0.002 0.002 0.002"/>
      </geometry>
    </collision>
  </link>
  <link name="mcnNNArka3">
    <inertial>
      <origin rpy="0 0 0" xyz="0 0 0"/>
      <mass value="0.03"/>
      <inertia ixx="0.1" ixy="0" ixz="0" iyy="0.1" iyz="0" izz="0.1"/>
    </inertial>
    <visual>
      <origin rpy="0 0 0" xyz="0 0 0"/>
      <geometry>
        <mesh filename="/home/samet/Desktop/robomaster-stl-files/wheels/mecanumroller.stl" scale="0.002 0.002 0.002"/>
      </geometry>
    </visual>
    <collision>
      <origin rpy="0 0 0" xyz="0 0 0"/>
      <geometry>
        <mesh filename="/home/samet/Desktop/robomaster-stl-files/wheels/mecanumroller.stl" scale="0.002 0.002 0.002"/>
      </geometry>
    </collision>
  </link>
  <link name="mcnNNArka4">
    <inertial>
      <origin rpy="0 0 0" xyz="0 0 0"/>
      <mass value="0.03"/>
      <inertia ixx="0.1" ixy="0" ixz="0" iyy="0.1" iyz="0" izz="0.1"/>
    </inertial>
    <visual>
      <origin rpy="0 0 0" xyz="0 0 0"/>
      <geometry>
        <mesh filename="/home/samet/Desktop/robomaster-stl-files/wheels/mecanumroller.stl" scale="0.002 0.002 0.002"/>
      </geometry>
    </visual>
    <collision>
      <origin rpy="0 0 0" xyz="0 0 0"/>
      <geometry>
        <mesh filename="/home/samet/Desktop/robomaster-stl-files/wheels/mecanumroller.stl" scale="0.002 0.002 0.002"/>
      </geometry>
    </collision>
  </link>
  <link name="mcnNNArka5">
    <inertial>
      <origin rpy="0 0 0" xyz="0 0 0"/>
      <mass value="0.03"/>
      <inertia ixx="0.1" ixy="0" ixz="0" iyy="0.1" iyz="0" izz="0.1"/>
    </inertial>
    <visual>
      <origin rpy="0 0 0" xyz="0 0 0"/>
      <geometry>
        <mesh filename="/home/samet/Desktop/robomaster-stl-files/wheels/mecanumroller.stl" scale="0.002 0.002 0.002"/>
      </geometry>
    </visual>
    <collision>
      <origin rpy="0 0 0" xyz="0 0 0"/>
      <geometry>
        <mesh filename="/home/samet/Desktop/robomaster-stl-files/wheels/mecanumroller.stl" scale="0.002 0.002 0.002"/>
      </geometry>
    </collision>
  </link>
  <link name="mcnNNArka6">
    <inertial>
      <origin rpy="0 0 0" xyz="0 0 0"/>
      <mass value="0.03"/>
      <inertia ixx="0.1" ixy="0" ixz="0" iyy="0.1" iyz="0" izz="0.1"/>
    </inertial>
    <visual>
      <origin rpy="0 0 0" xyz="0 0 0"/>
      <geometry>
        <mesh filename="/home/samet/Desktop/robomaster-stl-files/wheels/mecanumroller.stl" scale="0.002 0.002 0.002"/>
      </geometry>
    </visual>
    <collision>
      <origin rpy="0 0 0" xyz="0 0 0"/>
      <geometry>
        <mesh filename="/home/samet/Desktop/robomaster-stl-files/wheels/mecanumroller.stl" scale="0.002 0.002 0.002"/>
      </geometry>
    </collision>
  </link>
  <link name="mcnNNArka7">
    <inertial>
      <origin rpy="0 0 0" xyz="0 0 0"/>
      <mass value="0.03"/>
      <inertia ixx="0.1" ixy="0" ixz="0" iyy="0.1" iyz="0" izz="0.1"/>
    </inertial>
    <visual>
      <origin rpy="0 0 0" xyz="0 0 0"/>
      <geometry>
        <mesh filename="/home/samet/Desktop/robomaster-stl-files/wheels/mecanumroller.stl" scale="0.002 0.002 0.002"/>
      </geometry>
    </visual>
    <collision>
      <origin rpy="0 0 0" xyz="0 0 0"/>
      <geometry>
        <mesh filename="/home/samet/Desktop/robomaster-stl-files/wheels/mecanumroller.stl" scale="0.002 0.002 0.002"/>
      </geometry>
    </collision>
  </link>
  <link name="mcnNNArka8">
    <inertial>
      <origin rpy="0 0 0" xyz="0 0 0"/>
      <mass value="0.03"/>
      <inertia ixx="0.1" ixy="0" ixz="0" iyy="0.1" iyz="0" izz="0.1"/>
    </inertial>
    <visual>
      <origin rpy="0 0 0" xyz="0 0 0"/>
      <geometry>
        <mesh filename="/home/samet/Desktop/robomaster-stl-files/wheels/mecanumroller.stl" scale="0.002 0.002 0.002"/>
      </geometry>
    </visual>
    <collision>
      <origin rpy="0 0 0" xyz="0 0 0"/>
      <geometry>
        <mesh filename="/home/samet/Desktop/robomaster-stl-files/wheels/mecanumroller.stl" scale="0.002 0.002 0.002"/>
      </geometry>
    </collision>
  </link>
  <link name="mcnNNArka9">
    <inertial>
      <origin rpy="0 0 0" xyz="0 0 0"/>
      <mass value="0.03"/>
      <inertia ixx="0.1" ixy="0" ixz="0" iyy="0.1" iyz="0" izz="0.1"/>
    </inertial>
    <visual>
      <origin rpy="0 0 0" xyz="0 0 0"/>
      <geometry>
        <mesh filename="/home/samet/Desktop/robomaster-stl-files/wheels/mecanumroller.stl" scale="0.002 0.002 0.002"/>
      </geometry>
    </visual>
    <collision>
      <origin rpy="0 0 0" xyz="0 0 0"/>
      <geometry>
        <mesh filename="/home/samet/Desktop/robomaster-stl-files/wheels/mecanumroller.stl" scale="0.002 0.002 0.002"/>
      </geometry>
    </collision>
  </link>
  <joint name="jjjjoint1" type="continuous">
    <origin rpy="1.69616 -0.78865 -2.09076" xyz="0.08098 -0.03389 0.02632"/>
    <parent link="base_link4"/>
    <child link="mcnNNArka1"/>
    <axis xyz="1.0 0 0"/>
  </joint>
  <joint name="jjjjoint10" type="continuous">
    <origin rpy="0.16809 -2.34167 -0.52068" xyz="-0.03447 -0.08054 0.02726"/>
    <parent link="base_link4"/>
    <child link="mcnNNArka10"/>
    <axis xyz="1.0 0 0"/>
  </joint>
  <joint name="jjjjoint11" type="continuous">
    <origin rpy="0.20837 -2.34561 -0.00054" xyz="0.01035 -0.08714 0.02744"/>
    <parent link="base_link4"/>
    <child link="mcnNNArka11"/>
    <axis xyz="1.0 0 0"/>
  </joint>
  <joint name="jjjjoint12" type="continuous">
    <origin rpy="1.39158 -2.3543 0.52842" xyz="0.05215 -0.0703 0.02768"/>
    <parent link="base_link4"/>
    <child link="mcnNNArka12"/>
    <axis xyz="1.0 0 0"/>
  </joint>
  <joint name="jjjjoint2" type="continuous">
    <origin rpy="0.15693 -2.35442 1.57268" xyz="0.08702 0.01083 0.02674"/>
    <parent link="base_link4"/>
    <child link="mcnNNArka2"/>
    <axis xyz="1.0 0 0"/>
  </joint>
  <joint name="jjjjoint3" type="continuous">
    <origin rpy="1.99732 -0.78629 -1.0356" xyz="0.07027 0.0522 0.02725"/>
    <parent link="base_link4"/>
    <child link="mcnNNArka3"/>
    <axis xyz="1.0 0 0"/>
  </joint>
  <joint name="jjjjoint4" type="continuous">
    <origin rpy="-0.01116 -0.78641 -0.52158" xyz="0.03408 0.08081 0.02656"/>
    <parent link="base_link4"/>
    <child link="mcnNNArka4"/>
    <axis xyz="1.0 0 0"/>
  </joint>
  <joint name="jjjjoint5" type="continuous">
    <origin rpy="0.22604 -0.78465 0.00764" xyz="-0.00989 0.08688 0.02757"/>
    <parent link="base_link4"/>
    <child link="mcnNNArka5"/>
    <axis xyz="1.0 0 0"/>
  </joint>
  <joint name="jjjjoint6" type="continuous">
    <origin rpy="-0.92993 -0.78212 1.05974" xyz="-0.07998 0.03542 0.02784"/>
    <parent link="base_link4"/>
    <child link="mcnNNArka6"/>
    <axis xyz="1.0 0 0"/>
  </joint>
  <joint name="jjjjoint7" type="continuous">
    <origin rpy="-1.87163 -0.79217 0.5363" xyz="-0.05165 0.0708 0.02816"/>
    <parent link="base_link4"/>
    <child link="mcnNNArka7"/>
    <axis xyz="1.0 0 0"/>
  </joint>
  <joint name="jjjjoint8" type="continuous">
    <origin rpy="-1.50807 -0.79738 1.59404" xyz="-0.08668 -0.00986 0.02799"/>
    <parent link="base_link4"/>
    <child link="mcnNNArka8"/>
    <axis xyz="1.0 0 0"/>
  </joint>
  <joint name="jjjjoint9" type="continuous">
    <origin rpy="0.95433 -2.33443 -1.04334" xyz="-0.07027 -0.0525 0.02729"/>
    <parent link="base_link4"/>
    <child link="mcnNNArka9"/>
    <axis xyz="1.0 0 0"/>
  </joint>
  <joint name="joint_name2" type="continuous">
    <parent link="basee_link"/>
    <child link="base_link"/>
    <axis xyz="0 0 1"/>
    <origin rpy="0 0 0" xyz="0 0 0"/>
  </joint>
  <joint name="joint_name3" type="continuous">
    <parent link="basee_link"/>
    <child link="base_link2"/>
    <axis xyz="0 0 1"/>
    <origin rpy="0 0 0" xyz="0 0 0"/>
  </joint>
  <joint name="joint_name4" type="continuous">
    <parent link="basee_link"/>
    <child link="base_link3"/>
    <axis xyz="0 0 1"/>
    <origin rpy="0 0 0" xyz="0 0 0"/>
  </joint>
  <joint name="joint_name5" type="continuous">
    <parent link="basee_link"/>
    <child link="base_link4"/>
    <axis xyz="0 0 1"/>
    <origin rpy="0 0 0" xyz="0 0 0"/>
  </joint>
  <link name="basee_link">
    <visual>
      <geometry>
        <mesh filename="/home/samet/Desktop/robomaster-stl-files/wheels/base_link_centered.stl" scale="0.002 0.002 0.002"/>
      </geometry>
      <origin rpy="0 0 0" xyz="0 0 0"/>
    </visual>
    <collision>
      <geometry>
        <box size="0.3 0.3 0.2"/>
      </geometry>
      <origin rpy="0 0 0" xyz="0 0 0"/>
    </collision>
    <inertial>
      <origin rpy="0 0 0" xyz="0 0 0"/>
      <mass value="0.5"/>
      <inertia ixx="0.1" ixy="0.0" ixz="0.0" iyy="0.1" iyz="0.0" izz="0.1"/>
    </inertial>
  </link>
</robot>
