<?xml version="1.0"?>
<robot name="wheel">




<link name="base_link">
    <visual>
        <geometry>
            <mesh scale="0.002 0.002 0.002" filename="/home/samet/Desktop/robomaster-stl-files/wheels/mecanummain.stl"/>
        </geometry>
        <origin xyz="0 0 0" rpy="0 0 0"/>
    </visual>
    <collision>
        <geometry>
            <cylinder radius="0.1" length="0.08"/>
            <origin xyz="0 0 0" rpy="0 0 0"/>
        </geometry>
    </collision>
    <inertial>
        <mass value="0.5"/>
        <origin xyz="0 0 0"/>
        <inertia ixx="0.1" ixy="0.0" ixz="0.0" iyy="0.1" iyz="0.0" izz="0.1"/>
    </inertial>
</link>

<link name="mcn1">
    <visual>
        <geometry>
            <mesh scale="0.002 0.002 0.002" filename="/home/samet/Desktop/robomaster-stl-files/wheels/mecanumroller.stl"/>
        </geometry>
        <origin xyz="0 0 0" rpy="0 0 0"/>
    </visual>
    <collision>
    <geometry>
        <mesh scale="0.002 0.002 0.002" filename="/home/samet/Desktop/robomaster-stl-files/wheels/mecanumroller.stl"/>
    </geometry>
    <origin xyz="0 0 0" rpy="0 0 0"/>
    </collision>
    <inertial>
        <mass value="0.03"/>
        <inertia ixx="0.1" ixy="0.0" ixz="0.0" iyy="0.1" iyz="0.0" izz="0.1"/>
    </inertial>
</link>
<joint name="joint1" type="continuous">
    <parent link="base_link"/>
    <child link="mcn1"/>
    <axis xyz="0 1 0"/>
    <origin xyz="0 1.3 0" rpy="0 0 0"/>
</joint>

<link name="mcn2">
    <visual>
        <geometry>
            <mesh scale="0.002 0.002 0.002" filename="/home/samet/Desktop/robomaster-stl-files/wheels/mecanumroller.stl"/>
        </geometry>
        <origin xyz="0 0 0" rpy="0 0 0"/>
    </visual>
    <collision>
    <geometry>
        <mesh scale="0.002 0.002 0.002" filename="/home/samet/Desktop/robomaster-stl-files/wheels/mecanumroller.stl"/>
    </geometry>
    <origin xyz="0 0 0" rpy="0 0 0"/>
    </collision>
    <inertial>
        <mass value="0.03"/>
        <inertia ixx="0.1" ixy="0.0" ixz="0.0" iyy="0.1" iyz="0.0" izz="0.1"/>
    </inertial>
</link>
<joint name="joint2" type="continuous">
    <parent link="base_link"/>
    <child link="mcn2"/>
    <axis xyz="0 1 0"/>
    <origin xyz="0 1.2 0" rpy="0 0 0"/>
</joint>

<link name="mcn3">
    <visual>
        <geometry>
            <mesh scale="0.002 0.002 0.002" filename="/home/samet/Desktop/robomaster-stl-files/wheels/mecanumroller.stl"/>
        </geometry>
        <origin xyz="0 0 0" rpy="0 0 0"/>
    </visual>
    <collision>
    <geometry>
        <mesh scale="0.002 0.002 0.002" filename="/home/samet/Desktop/robomaster-stl-files/wheels/mecanumroller.stl"/>
    </geometry>
    <origin xyz="0 0 0" rpy="0 0 0"/>
    </collision>
    <inertial>
        <mass value="0.03"/>
        <inertia ixx="0.1" ixy="0.0" ixz="0.0" iyy="0.1" iyz="0.0" izz="0.1"/>
    </inertial>
</link>
<joint name="joint3" type="continuous">
    <parent link="base_link"/>
    <child link="mcn3"/>
    <axis xyz="0 1 0"/>
    <origin xyz="0 1.1 0" rpy="0 0 0"/>
</joint>

<link name="mcn4">
    <visual>
        <geometry>
            <mesh scale="0.002 0.002 0.002" filename="/home/samet/Desktop/robomaster-stl-files/wheels/mecanumroller.stl"/>
        </geometry>
        <origin xyz="0 0 0" rpy="0 0 0"/>
    </visual>
    <collision>
    <geometry>
        <mesh scale="0.002 0.002 0.002" filename="/home/samet/Desktop/robomaster-stl-files/wheels/mecanumroller.stl"/>
    </geometry>
    <origin xyz="0 0 0" rpy="0 0 0"/>
    </collision>
    <inertial>
        <mass value="0.03"/>
        <inertia ixx="0.1" ixy="0.0" ixz="0.0" iyy="0.1" iyz="0.0" izz="0.1"/>
    </inertial>
</link>
<joint name="joint4" type="continuous">
    <parent link="base_link"/>
    <child link="mcn4"/>
    <axis xyz="0 1 0"/>
    <origin xyz="0 1 0" rpy="0 0 0"/>
</joint>

<link name="mcn5">
    <visual>
        <geometry>
            <mesh scale="0.002 0.002 0.002" filename="/home/samet/Desktop/robomaster-stl-files/wheels/mecanumroller.stl"/>
        </geometry>
        <origin xyz="0 0 0" rpy="0 0 0"/>
    </visual>
    <collision>
    <geometry>
        <mesh scale="0.002 0.002 0.002" filename="/home/samet/Desktop/robomaster-stl-files/wheels/mecanumroller.stl"/>
    </geometry>
    <origin xyz="0 0 0" rpy="0 0 0"/>
    </collision>
    <inertial>
        <mass value="0.03"/>
        <inertia ixx="0.1" ixy="0.0" ixz="0.0" iyy="0.1" iyz="0.0" izz="0.1"/>
    </inertial>
</link>
<joint name="joint5" type="continuous">
    <parent link="base_link"/>
    <child link="mcn5"/>
    <axis xyz="0 1 0"/>
    <origin xyz="0 0.9 0" rpy="0 0 0"/>
</joint>

<link name="mcn6">
    <visual>
        <geometry>
            <mesh scale="0.002 0.002 0.002" filename="/home/samet/Desktop/robomaster-stl-files/wheels/mecanumroller.stl"/>
        </geometry>
        <origin xyz="0 0 0" rpy="0 0 0"/>
    </visual>
    <collision>
    <geometry>
        <mesh scale="0.002 0.002 0.002" filename="/home/samet/Desktop/robomaster-stl-files/wheels/mecanumroller.stl"/>
    </geometry>
    <origin xyz="0 0 0" rpy="0 0 0"/>
    </collision>
    <inertial>
        <mass value="0.03"/>
        <inertia ixx="0.1" ixy="0.0" ixz="0.0" iyy="0.1" iyz="0.0" izz="0.1"/>
    </inertial>
</link>
<joint name="joint6" type="continuous">
    <parent link="base_link"/>
    <child link="mcn6"/>
    <axis xyz="0 1 0"/>
    <origin xyz="0 0.8 0" rpy="0 0 0"/>
</joint>

<link name="mcn7">
    <visual>
        <geometry>
            <mesh scale="0.002 0.002 0.002" filename="/home/samet/Desktop/robomaster-stl-files/wheels/mecanumroller.stl"/>
        </geometry>
        <origin xyz="0 0 0" rpy="0 0 0"/>
    </visual>
    <collision>
    <geometry>
        <mesh scale="0.002 0.002 0.002" filename="/home/samet/Desktop/robomaster-stl-files/wheels/mecanumroller.stl"/>
    </geometry>
    <origin xyz="0 0 0" rpy="0 0 0"/>
    </collision>
    <inertial>
        <mass value="0.03"/>
        <inertia ixx="0.1" ixy="0.0" ixz="0.0" iyy="0.1" iyz="0.0" izz="0.1"/>
    </inertial>
</link>
<joint name="joint7" type="continuous">
    <parent link="base_link"/>
    <child link="mcn7"/>
    <axis xyz="0 1 0"/>
    <origin xyz="0 0.7 0" rpy="0 0 0"/>
</joint>

<link name="mcn8">
    <visual>
        <geometry>
            <mesh scale="0.002 0.002 0.002" filename="/home/samet/Desktop/robomaster-stl-files/wheels/mecanumroller.stl"/>
        </geometry>
        <origin xyz="0 0 0" rpy="0 0 0"/>
    </visual>
    <collision>
    <geometry>
        <mesh scale="0.002 0.002 0.002" filename="/home/samet/Desktop/robomaster-stl-files/wheels/mecanumroller.stl"/>
    </geometry>
    <origin xyz="0 0 0" rpy="0 0 0"/>
    </collision>
    <inertial>
        <mass value="0.03"/>
        <inertia ixx="0.1" ixy="0.0" ixz="0.0" iyy="0.1" iyz="0.0" izz="0.1"/>
    </inertial>
</link>
<joint name="joint8" type="continuous">
    <parent link="base_link"/>
    <child link="mcn8"/>
    <axis xyz="0 1 0"/>
    <origin xyz="0 0.6 0" rpy="0 0 0"/>
</joint>

<link name="mcn9">
    <visual>
        <geometry>
            <mesh scale="0.002 0.002 0.002" filename="/home/samet/Desktop/robomaster-stl-files/wheels/mecanumroller.stl"/>
        </geometry>
        <origin xyz="0 0 0" rpy="0 0 0"/>
    </visual>
    <collision>
    <geometry>
        <mesh scale="0.002 0.002 0.002" filename="/home/samet/Desktop/robomaster-stl-files/wheels/mecanumroller.stl"/>
    </geometry>
    <origin xyz="0 0 0" rpy="0 0 0"/>
    </collision>
    <inertial>
        <mass value="0.03"/>
        <inertia ixx="0.1" ixy="0.0" ixz="0.0" iyy="0.1" iyz="0.0" izz="0.1"/>
    </inertial>
</link>
<joint name="joint9" type="continuous">
    <parent link="base_link"/>
    <child link="mcn9"/>
    <axis xyz="0 1 0"/>
    <origin xyz="0 0.5 0" rpy="0 0 0"/>
</joint>


<link name="mcn10">
    <visual>
        <geometry>
            <mesh scale="0.002 0.002 0.002" filename="/home/samet/Desktop/robomaster-stl-files/wheels/mecanumroller.stl"/>
        </geometry>
        <origin xyz="0 0 0" rpy="0 0 0"/>
    </visual>
    <collision>
    <geometry>
        <mesh scale="0.002 0.002 0.002" filename="/home/samet/Desktop/robomaster-stl-files/wheels/mecanumroller.stl"/>
    </geometry>
    <origin xyz="0 0 0" rpy="0 0 0"/>
    </collision>
    <inertial>
        <mass value="0.03"/>
        <inertia ixx="0.1" ixy="0.0" ixz="0.0" iyy="0.1" iyz="0.0" izz="0.1"/>
    </inertial>
</link>
<joint name="joint10" type="continuous">
    <parent link="base_link"/>
    <child link="mcn10"/>
    <axis xyz="0 1 0"/>
    <origin xyz="0 0.4 0" rpy="0 0 0"/>
</joint>


<link name="mcn11">
    <visual>
        <geometry>
            <mesh scale="0.002 0.002 0.002" filename="/home/samet/Desktop/robomaster-stl-files/wheels/mecanumroller.stl"/>
        </geometry>
        <origin xyz="0 0 0" rpy="0 0 0"/>
    </visual>
    <collision>
    <geometry>
        <mesh scale="0.002 0.002 0.002" filename="/home/samet/Desktop/robomaster-stl-files/wheels/mecanumroller.stl"/>
    </geometry>
    <origin xyz="0 0 0" rpy="0 0 0"/>
    </collision>
    <inertial>
        <mass value="0.03"/>
        <inertia ixx="0.1" ixy="0.0" ixz="0.0" iyy="0.1" iyz="0.0" izz="0.1"/>
    </inertial>
</link>
<joint name="joint11" type="continuous">
    <parent link="base_link"/>
    <child link="mcn11"/>
    <axis xyz="0 1 0"/>
    <origin xyz="0 0.3 0" rpy="0 0 0"/>
</joint>


<link name="mcn12">
    <visual>
        <geometry>
            <mesh scale="0.002 0.002 0.002" filename="/home/samet/Desktop/robomaster-stl-files/wheels/mecanumroller.stl"/>
        </geometry>
        <origin xyz="0 0 0" rpy="0 0 0"/>
    </visual>
    <collision>
    <geometry>
        <mesh scale="0.002 0.002 0.002" filename="/home/samet/Desktop/robomaster-stl-files/wheels/mecanumroller.stl"/>
    </geometry>
    <origin xyz="0 0 0" rpy="0 0 0"/>
    </collision>
    <inertial>
        <mass value="0.03"/>
        <inertia ixx="0.1" ixy="0.0" ixz="0.0" iyy="0.1" iyz="0.0" izz="0.1"/>
    </inertial>
</link>
<joint name="joint12" type="continuous">
    <parent link="base_link"/>
    <child link="mcn12"/>
    <axis xyz="0 1 0"/>
    <origin xyz="0 0.2 0" rpy="0 0 0"/>
</joint>

</robot>